Workbook

Sheet Assessment Sheet
A1: ID | B1: Chapter | C1: Section | D1: Enforcement Component | E1: Requirement | F1: Minimum level | G1: L1 | H1: L2 | I1: L3 | J1: Applicability | K1: Status | L1: Evidence and Notes | M1: Owner | N1: Planned Completion | O1: Level No.
A2: V1.1.1 | B2: V1 Identity and Authentication | C2: V1.1 User Authentication | D2: Identity layer | E2: The platform and all its channels shall allow login only through the enterprise IdP (OIDC or SAML) and shall not provide independent local accounts, except for the break-glass accounts specified in V10.5 | F2: L1 | G2: ✓ | H2: ✓ | I2: ✓ | J2: All platforms | K2: Not assessed | O2: =VALUE(RIGHT(F2,1)) -> 1
A3: V1.1.2 | B3: V1 Identity and Authentication | C3: V1.1 User Authentication | D3: Identity layer | E3: Users and groups shall be synchronized through SCIM or an equivalent mechanism, and users disabled in the IdP shall be disabled in the platform in sync | F3: L2 | H3: ✓ | I3: ✓ | J3: All platforms | K3: Not assessed | O3: =VALUE(RIGHT(F3,1)) -> 2
A4: V1.1.3 | B4: V1 Identity and Authentication | C4: V1.1 User Authentication | D4: Identity layer | E4: The authentication time and authentication strength issued by the IdP shall be retained in the user session for use in the step-up authentication decisions of V3.5 | F4: L2 | H4: ✓ | I4: ✓ | J4: All platforms | K4: Not assessed | O4: =VALUE(RIGHT(F4,1)) -> 2
A5: V1.1.4 | B5: V1 Identity and Authentication | C5: V1.1 User Authentication | D5: Identity layer | E5: Credentials used to invoke agents through an API (such as API keys and personal access tokens) shall be bound to a specific user or non-human identity in the enterprise IdP, shall have an expiration time and a permission scope set, and shall be revoked automatically when the identity is disabled | F5: L1 | G5: ✓ | H5: ✓ | I5: ✓ | J5: All platforms | K5: Not assessed | O5: =VALUE(RIGHT(F5,1)) -> 1
A6: V1.2.1 | B6: V1 Identity and Authentication | C6: V1.2 Channel Identity Mapping | D6: Interaction channel | E6: A channel account shall be bound to an enterprise identity through a one-time SSO login before it can invoke an agent | F6: L1 | G6: ✓ | H6: ✓ | I6: ✓ | J6: Platforms that support third-party channels such as IM, email, and browser extensions | K6: Not assessed | O6: =VALUE(RIGHT(F6,1)) -> 1
A7: V1.2.2 | B7: V1 Identity and Authentication | C7: V1.2 Channel Identity Mapping | D7: Interaction channel | E7: The SSO binding result shall be the sole basis for identifying a channel account. Matching by nickname, display name, or email string is not permitted. The email channel follows V1.2.6. | F7: L1 | G7: ✓ | H7: ✓ | I7: ✓ | J7: Platforms that support third-party channels such as IM, email, and browser extensions | K7: Not assessed | O7: =VALUE(RIGHT(F7,1)) -> 1
A8: V1.2.3 | B8: V1 Identity and Authentication | C8: V1.2 Channel Identity Mapping | D8: Interaction channel | E8: When a user is disabled in the IdP, all of that user's channel bindings shall be invalidated in sync | F8: L2 | H8: ✓ | I8: ✓ | J8: Platforms that support third-party channels such as IM, email, and browser extensions | K8: Not assessed | O8: =VALUE(RIGHT(F8,1)) -> 2
A9: V1.2.4 | B9: V1 Identity and Authentication | C9: V1.2 Channel Identity Mapping | D9: Interaction channel | E9: Accounts from external visitors and from cross-organization shared channels shall be identified, and the agents and capabilities available to them shall be restricted separately | F9: L2 | H9: ✓ | I9: ✓ | J9: Platforms that support third-party channels such as IM, email, and browser extensions | K9: Not assessed | O9: =VALUE(RIGHT(F9,1)) -> 2
A10: V1.2.5 | B10: V1 Identity and Authentication | C10: V1.2 Channel Identity Mapping | D10: Interaction channel | E10: When a high-risk operation is triggered within a channel, the user shall be required to complete step-up authentication through the enterprise IdP | F10: L2 | H10: ✓ | I10: ✓ | J10: Platforms that support third-party channels such as IM, email, and browser extensions | K10: Not assessed | O10: =VALUE(RIGHT(F10,1)) -> 2
A11: V1.2.6 | B11: V1 Identity and Authentication | C11: V1.2 Channel Identity Mapping | D11: Interaction channel | E11: The email channel shall accept only email that passes DMARC verification (SPF or DKIM passing and aligned with the From domain). Senders from external domains shall not be able to trigger operations on behalf of a user. | F11: L1 | G11: ✓ | H11: ✓ | I11: ✓ | J11: Platforms that support third-party channels such as IM, email, and browser extensions | K11: Not assessed | O11: =VALUE(RIGHT(F11,1)) -> 1
A12: V1.3.1 | B12: V1 Identity and Authentication | C12: V1.3 Agent Identity | D12: Identity layer | E12: Each agent shall have a unique identifier issued by the platform. The platform shall not accept identities self-reported by the agent. | F12: L1 | G12: ✓ | H12: ✓ | I12: ✓ | J12: All platforms | K12: Not assessed | O12: =VALUE(RIGHT(F12,1)) -> 1
A13: V1.3.2 | B13: V1 Identity and Authentication | C13: V1.3 Agent Identity | D13: Identity layer | E13: An independent non-human identity shall be established in the enterprise directory for each autonomous agent. No employee's personal account shall be used. | F13: L1 | G13: ✓ | H13: ✓ | I13: ✓ | J13: All platforms | K13: Not assessed | O13: =VALUE(RIGHT(F13,1)) -> 1
A14: V1.3.3 | B14: V1 Identity and Authentication | C14: V1.3 Agent Identity | D14: Downstream systems | E14: When an autonomous agent accesses downstream systems, it shall use the identity established under V1.3.2, and the principal recorded in downstream logs shall be that agent | F14: L2 | H14: ✓ | I14: ✓ | J14: All platforms | K14: Not assessed | O14: =VALUE(RIGHT(F14,1)) -> 2
A15: V1.3.4 | B15: V1 Identity and Authentication | C15: V1.3 Agent Identity | D15: Identity layer | E15: When an autonomous agent accesses downstream systems, it shall use short-lived tokens and shall not use long-term static keys | F15: L2 | H15: ✓ | I15: ✓ | J15: All platforms | K15: Not assessed | O15: =VALUE(RIGHT(F15,1)) -> 2
A16: V1.3.5 | B16: V1 Identity and Authentication | C16: V1.3 Agent Identity | D16: Identity layer | E16: The keys and certificates of an autonomous agent shall have processes for issuance, rotation, and revocation, and the rotation period shall have an upper limit | F16: L2 | H16: ✓ | I16: ✓ | J16: All platforms | K16: Not assessed | O16: =VALUE(RIGHT(F16,1)) -> 2
A17: V1.4.1 | B17: V1 Identity and Authentication | C17: V1.4 Workload Identity | D17: Identity layer | E17: The platform shall issue a short-lived workload identity to the execution instance of each session and bind it to that instance | F17: L1 | G17: ✓ | H17: ✓ | I17: ✓ | J17: Platforms that assign an independent execution instance (such as a container, sandbox, or virtual machine) to each session | K17: Not assessed | O17: =VALUE(RIGHT(F17,1)) -> 1
A18: V1.4.2 | B18: V1 Identity and Authentication | C18: V1.4 Workload Identity | D18: Harness | E18: The credentials of the workload identity shall be invisible to the model and shall not enter the context or tool return values | F18: L1 | G18: ✓ | H18: ✓ | I18: ✓ | J18: Platforms that assign an independent execution instance (such as a container, sandbox, or virtual machine) to each session | K18: Not assessed | O18: =VALUE(RIGHT(F18,1)) -> 1
A19: V1.4.3 | B19: V1 Identity and Authentication | C19: V1.4 Workload Identity | D19: Egress gateway | E19: The egress gateway shall determine the user and agent solely from the workload identity and shall ignore user or agent identifiers self-reported in the request | F19: L1 | G19: ✓ | H19: ✓ | I19: ✓ | J19: Platforms that assign an independent execution instance (such as a container, sandbox, or virtual machine) to each session | K19: Not assessed | O19: =VALUE(RIGHT(F19,1)) -> 1
A20: V1.4.4 | B20: V1 Identity and Authentication | C20: V1.4 Workload Identity | D20: Identity layer | E20: When a session ends or an execution instance is destroyed, the corresponding workload identity shall be revoked immediately | F20: L2 | H20: ✓ | I20: ✓ | J20: Platforms that assign an independent execution instance (such as a container, sandbox, or virtual machine) to each session | K20: Not assessed | O20: =VALUE(RIGHT(F20,1)) -> 2
A21: V1.4.5 | B21: V1 Identity and Authentication | C21: V1.4 Workload Identity | D21: Identity layer | E21: Before issuing a workload identity, the platform shall perform workload attestation on the execution instance (such as node attestation and workload attestation in SPIFFE/SPIRE). The identity shall not be issued if attestation fails. | F21: L3 | I21: ✓ | J21: Platforms that assign an independent execution instance (such as a container, sandbox, or virtual machine) to each session | K21: Not assessed | O21: =VALUE(RIGHT(F21,1)) -> 3
A22: V1.5.1 | B22: V1 Identity and Authentication | C22: V1.5 External Principals | D22: Identity layer | E22: External principals shall be accessed through identity federation, and no shared account shall be created for them | F22: L2 | H22: ✓ | I22: ✓ | J22: Platforms that open agent capabilities to customers or partners | K22: Not assessed | O22: =VALUE(RIGHT(F22,1)) -> 2
A23: V1.5.2 | B23: V1 Identity and Authentication | C23: V1.5 External Principals | D23: Policy decision point | E23: External principals shall have access only to the workspaces and interfaces made available to them | F23: L1 | G23: ✓ | H23: ✓ | I23: ✓ | J23: Platforms that open agent capabilities to customers or partners | K23: Not assessed | O23: =VALUE(RIGHT(F23,1)) -> 1
A24: V1.5.3 | B24: V1 Identity and Authentication | C24: V1.5 External Principals | D24: Audit | E24: Invocations by external principals shall be recorded separately in the audit log and shall be filterable by external organization | F24: L2 | H24: ✓ | I24: ✓ | J24: Platforms that open agent capabilities to customers or partners | K24: Not assessed | O24: =VALUE(RIGHT(F24,1)) -> 2
A25: V2.1.1 | B25: V2 Delegation and Effective Permissions | C25: V2.1 Access on Behalf of a User | D25: Egress gateway | E25: When the user is present, an agent accessing downstream systems shall carry the identity of the initiating user, and the downstream system shall make its authorization decision based on that user. Downstream systems that do not support user-level authorization decisions are handled under V4.4. | F25: L1 | G25: ✓ | H25: ✓ | I25: ✓ | J25: All platforms | K25: Not assessed | O25: =VALUE(RIGHT(F25,1)) -> 1
A26: V2.1.2 | B26: V2 Delegation and Effective Permissions | C26: V2.1 Access on Behalf of a User | D26: Egress gateway | E26: Shared credentials with higher permissions than the initiating user shall not be used to access downstream systems on the user's behalf. Downstream systems that support only shared static credentials are handled by compensating controls under V4.4. | F26: L1 | G26: ✓ | H26: ✓ | I26: ✓ | J26: All platforms | K26: Not assessed | O26: =VALUE(RIGHT(F26,1)) -> 1
A27: V2.1.3 | B27: V2 Delegation and Effective Permissions | C27: V2.1 Access on Behalf of a User | D27: Identity layer | E27: Downstream tokens shall identify both the initiating user and the executing agent (such as the act claim in RFC 8693) | F27: L2 | H27: ✓ | I27: ✓ | J27: All platforms | K27: Not assessed | O27: =VALUE(RIGHT(F27,1)) -> 2
A28: V2.2.1 | B28: V2 Delegation and Effective Permissions | C28: V2.2 Effective Permissions | D28: Policy decision point | E28: The effective permissions of each invocation shall be the intersection of the user's permissions and the agent authorization scope | F28: L1 | G28: ✓ | H28: ✓ | I28: ✓ | J28: All platforms | K28: Not assessed | O28: =VALUE(RIGHT(F28,1)) -> 1
A29: V2.2.2 | B29: V2 Delegation and Effective Permissions | C29: V2.2 Effective Permissions | D29: Policy decision point | E29: Effective permissions shall be computed by the policy decision point and shall not depend on the system prompt or on the model's judgment | F29: L1 | G29: ✓ | H29: ✓ | I29: ✓ | J29: All platforms | K29: Not assessed | O29: =VALUE(RIGHT(F29,1)) -> 1
A30: V2.2.3 | B30: V2 Delegation and Effective Permissions | C30: V2.2 Effective Permissions | D30: Policy decision point | E30: At the start of a task, the required tool and data scope shall be declared. During execution, only permissions within the declared scope shall be granted. The declaration is provided by the user or by agent configuration, and any scope proposed by the model shall take effect only after user confirmation. | F30: L2 | H30: ✓ | I30: ✓ | J30: All platforms | K30: Not assessed | O30: =VALUE(RIGHT(F30,1)) -> 2
A31: V2.2.4 | B31: V2 Delegation and Effective Permissions | C31: V2.2 Effective Permissions | D31: Policy decision point | E31: Invocations beyond the task's declared scope shall be rejected or require approval | F31: L2 | H31: ✓ | I31: ✓ | J31: All platforms | K31: Not assessed | O31: =VALUE(RIGHT(F31,1)) -> 2
A32: V2.2.5 | B32: V2 Delegation and Effective Permissions | C32: V2.2 Effective Permissions | D32: Policy decision point | E32: Effective permissions shall be recomputed on each tool invocation and shall not reuse the authorization result from the start of the session | F32: L2 | H32: ✓ | I32: ✓ | J32: All platforms | K32: Not assessed | O32: =VALUE(RIGHT(F32,1)) -> 2
A33: V2.2.6 | B33: V2 Delegation and Effective Permissions | C33: V2.2 Effective Permissions | D33: Policy decision point | E33: Authorization for high-risk operations shall be refined to specific resources and parameters (for example, using RFC 9396 Rich Authorization Requests to describe the authorization details) and shall not grant only coarse-grained roles | F33: L3 | I33: ✓ | J33: All platforms | K33: Not assessed | O33: =VALUE(RIGHT(F33,1)) -> 3
A34: V2.3.1 | B34: V2 Delegation and Effective Permissions | C34: V2.3 Offline Delegated Tasks | D34: Policy decision point | E34: An offline delegated task shall be rooted in its creating user. The permission upper limit shall be fixed at creation and can only be narrowed thereafter. | F34: L1 | G34: ✓ | H34: ✓ | I34: ✓ | J34: Platforms that support scheduled or long-running tasks | K34: Not assessed | O34: =VALUE(RIGHT(F34,1)) -> 1
A35: V2.3.2 | B35: V2 Delegation and Effective Permissions | C35: V2.3 Offline Delegated Tasks | D35: Policy decision point | E35: The account status and current permissions of the creating user shall be rechecked before each run | F35: L1 | G35: ✓ | H35: ✓ | I35: ✓ | J35: Platforms that support scheduled or long-running tasks | K35: Not assessed | O35: =VALUE(RIGHT(F35,1)) -> 1
A36: V2.3.3 | B36: V2 Delegation and Effective Permissions | C36: V2.3 Offline Delegated Tasks | D36: Harness | E36: The scheduler shall store only task identifiers and shall not store user credentials or directly usable tokens | F36: L1 | G36: ✓ | H36: ✓ | I36: ✓ | J36: Platforms that support scheduled or long-running tasks | K36: Not assessed | O36: =VALUE(RIGHT(F36,1)) -> 1
A37: V2.3.4 | B37: V2 Delegation and Effective Permissions | C37: V2.3 Offline Delegated Tasks | D37: Management plane | E37: When the creating user is disabled, their offline delegated tasks shall stop automatically, and the owner of the agent shall be notified | F37: L2 | H37: ✓ | I37: ✓ | J37: Platforms that support scheduled or long-running tasks | K37: Not assessed | O37: =VALUE(RIGHT(F37,1)) -> 2
A38: V2.3.5 | B38: V2 Delegation and Effective Permissions | C38: V2.3 Offline Delegated Tasks | D38: Management plane | E38: For tasks that must continue running after the creating user leaves or changes roles, the tasks shall be converted to autonomous agents and reauthorized through approval before the user's account is disabled | F38: L2 | H38: ✓ | I38: ✓ | J38: Platforms that support scheduled or long-running tasks | K38: Not assessed | O38: =VALUE(RIGHT(F38,1)) -> 2
A39: V2.3.6 | B39: V2 Delegation and Effective Permissions | C39: V2.3 Offline Delegated Tasks | D39: Policy decision point | E39: The authorization for an offline delegated task shall have an expiration time, after which the creating user must reconfirm it | F39: L2 | H39: ✓ | I39: ✓ | J39: Platforms that support scheduled or long-running tasks | K39: Not assessed | O39: =VALUE(RIGHT(F39,1)) -> 2
A40: V2.4.1 | B40: V2 Delegation and Effective Permissions | C40: V2.4 Inter-Agent Delegation | D40: Policy decision point | E40: The effective permissions of a downstream agent shall not exceed the permissions of the initiating user or the delegation scope granted by the upstream agent. The initiating user shall not obtain, through a downstream agent, permissions that the user does not hold. | F40: L1 | G40: ✓ | H40: ✓ | I40: ✓ | J40: Platforms that support multi-agent collaboration or sub-agents | K40: Not assessed | O40: =VALUE(RIGHT(F40,1)) -> 1
...

Sheet Summary
A1: Assessment Progress
A2: Figures are calculated live by formulas from “Assessment Sheet”. Items within a target level = all items at that level and below; conformance rate = met ÷ (items − not applicable); not assessed counts as unmet.
A4: Target Level | B4: Items | C4: Met | D4: Partially Met | E4: Unmet | F4: Not applicable | G4: Not assessed | H4: Conformance Rate | I4: Result
A5: Reach L1 | B5: =COUNTIFS('Assessment Sheet'!$O$2:$O$241,"<=1") -> 90 | C5: =COUNTIFS('Assessment Sheet'!$O$2:$O$241,"<=1",'Assessment Sheet'!$K$2:$K$241,"Met") -> 0 | D5: =COUNTIFS('Assessment Sheet'!$O$2:$O$241,"<=1",'Assessment Sheet'!$K$2:$K$241,"Partially Met") -> 0 | E5: =COUNTIFS('Assessment Sheet'!$O$2:$O$241,"<=1",'Assessment Sheet'!$K$2:$K$241,"Unmet") -> 0 | F5: =COUNTIFS('Assessment Sheet'!$O$2:$O$241,"<=1",'Assessment Sheet'!$K$2:$K$241,"Not applicable") -> 0 | G5: =B5-SUM(C5:F5) -> 90 | H5: =IF(B5-F5=0,"—",C5/(B5-F5)) -> 0 | I5: =IF(C5=B5-F5,"Reached","Not reached") -> Not reached
A6: Reach L2 | B6: =COUNTIFS('Assessment Sheet'!$O$2:$O$241,"<=2") -> 227 | C6: =COUNTIFS('Assessment Sheet'!$O$2:$O$241,"<=2",'Assessment Sheet'!$K$2:$K$241,"Met") -> 0 | D6: =COUNTIFS('Assessment Sheet'!$O$2:$O$241,"<=2",'Assessment Sheet'!$K$2:$K$241,"Partially Met") -> 0 | E6: =COUNTIFS('Assessment Sheet'!$O$2:$O$241,"<=2",'Assessment Sheet'!$K$2:$K$241,"Unmet") -> 0 | F6: =COUNTIFS('Assessment Sheet'!$O$2:$O$241,"<=2",'Assessment Sheet'!$K$2:$K$241,"Not applicable") -> 0 | G6: =B6-SUM(C6:F6) -> 227 | H6: =IF(B6-F6=0,"—",C6/(B6-F6)) -> 0 | I6: =IF(C6=B6-F6,"Reached","Not reached") -> Not reached
A7: Reach L3 | B7: =COUNTIFS('Assessment Sheet'!$O$2:$O$241,"<=3") -> 240 | C7: =COUNTIFS('Assessment Sheet'!$O$2:$O$241,"<=3",'Assessment Sheet'!$K$2:$K$241,"Met") -> 0 | D7: =COUNTIFS('Assessment Sheet'!$O$2:$O$241,"<=3",'Assessment Sheet'!$K$2:$K$241,"Partially Met") -> 0 | E7: =COUNTIFS('Assessment Sheet'!$O$2:$O$241,"<=3",'Assessment Sheet'!$K$2:$K$241,"Unmet") -> 0 | F7: =COUNTIFS('Assessment Sheet'!$O$2:$O$241,"<=3",'Assessment Sheet'!$K$2:$K$241,"Not applicable") -> 0 | G7: =B7-SUM(C7:F7) -> 240 | H7: =IF(B7-F7=0,"—",C7/(B7-F7)) -> 0 | I7: =IF(C7=B7-F7,"Reached","Not reached") -> Not reached
A10: The three tables below are calculated for this target level ▸ | B10: L2 | C10: (switch between L1 / L2 / L3 in the drop-down)
A12: 按架构组件
A13: 架构组件 | B13: L1 | C13: New in L2 | D13: New in L3 | E13: Total | F13: Items in target | G13: Met | H13: Partially Met | I13: Unmet | J13: Not applicable | K13: Not assessed | L13: Conformance Rate | M13: Achieved Level
A14: Identity layer | B14: =COUNTIFS('Assessment Sheet'!$D$2:$D$241,$A14,'Assessment Sheet'!$F$2:$F$241,"L1") -> 7 | C14: =COUNTIFS('Assessment Sheet'!$D$2:$D$241,$A14,'Assessment Sheet'!$F$2:$F$241,"L2") -> 12 | D14: =COUNTIFS('Assessment Sheet'!$D$2:$D$241,$A14,'Assessment Sheet'!$F$2:$F$241,"L3") -> 3 | E14: =SUM(B14:D14) -> 22 | F14: =COUNTIFS('Assessment Sheet'!$D$2:$D$241,$A14,'Assessment Sheet'!$O$2:$O$241,"<="&VALUE(RIGHT($B$10,1))) -> 19 | G14: =COUNTIFS('Assessment Sheet'!$D$2:$D$241,$A14,'Assessment Sheet'!$O$2:$O$241,"<="&VALUE(RIGHT($B$10,1)),'Assessment Sheet'!$K$2:$K$241,"Met") -> 0 | H14: =COUNTIFS('Assessment Sheet'!$D$2:$D$241,$A14,'Assessment Sheet'!$O$2:$O$241,"<="&VALUE(RIGHT($B$10,1)),'Assessment Sheet'!$K$2:$K$241,"Partially Met") -> 0 | I14: =COUNTIFS('Assessment Sheet'!$D$2:$D$241,$A14,'Assessment Sheet'!$O$2:$O$241,"<="&VALUE(RIGHT($B$10,1)),'Assessment Sheet'!$K$2:$K$241,"Unmet") -> 0 | J14: =COUNTIFS('Assessment Sheet'!$D$2:$D$241,$A14,'Assessment Sheet'!$O$2:$O$241,"<="&VALUE(RIGHT($B$10,1)),'Assessment Sheet'!$K$2:$K$241,"Not applicable") -> 0 | K14: =F14-SUM(G14:J14) -> 19 | L14: =IF(F14-J14=0,"—",G14/(F14-J14)) -> 0 | M14: =IF(COUNTIFS('Assessment Sheet'!$D$2:$D$241,$A14,'Assessment Sheet'!$O$2:$O$241,"<=1",'Assessment Sheet'!$K$2:$K$241,"<>Met",'Assessment Sheet'!$K$2:$K$241,"<>Not applicable")>0,"Below L1",IF(COUNTIFS('Assessment Sheet'!$D$2:$D$241,$A14,'Assessment Sheet'!$O$2:$O$241,"<=2",'Assessment Sheet'!$K$2:$K$241,"<>Met",'Assessment Sheet'!$K$2:$K$241,"<>Not applicable")>0,"L1",IF(COUNTIFS('Assessment Sheet'!$D$2:$D$241,$A14,'Assessment Sheet'!$O$2:$O$241,"<=3",'Assessment Sheet'!$K$2:$K$241,"<>Met",'Assessment Sheet'!$K$2:$K$241,"<>Not applicable")>0,"L2","L3"))) -> Below L1
A15: Interaction channel | B15: =COUNTIFS('Assessment Sheet'!$D$2:$D$241,$A15,'Assessment Sheet'!$F$2:$F$241,"L1") -> 8 | C15: =COUNTIFS('Assessment Sheet'!$D$2:$D$241,$A15,'Assessment Sheet'!$F$2:$F$241,"L2") -> 10 | D15: =COUNTIFS('Assessment Sheet'!$D$2:$D$241,$A15,'Assessment Sheet'!$F$2:$F$241,"L3") -> 0 | E15: =SUM(B15:D15) -> 18 | F15: =COUNTIFS('Assessment Sheet'!$D$2:$D$241,$A15,'Assessment Sheet'!$O$2:$O$241,"<="&VALUE(RIGHT($B$10,1))) -> 18 | G15: =COUNTIFS('Assessment Sheet'!$D$2:$D$241,$A15,'Assessment Sheet'!$O$2:$O$241,"<="&VALUE(RIGHT($B$10,1)),'Assessment Sheet'!$K$2:$K$241,"Met") -> 0 | H15: =COUNTIFS('Assessment Sheet'!$D$2:$D$241,$A15,'Assessment Sheet'!$O$2:$O$241,"<="&VALUE(RIGHT($B$10,1)),'Assessment Sheet'!$K$2:$K$241,"Partially Met") -> 0 | I15: =COUNTIFS('Assessment Sheet'!$D$2:$D$241,$A15,'Assessment Sheet'!$O$2:$O$241,"<="&VALUE(RIGHT($B$10,1)),'Assessment Sheet'!$K$2:$K$241,"Unmet") -> 0 | J15: =COUNTIFS('Assessment Sheet'!$D$2:$D$241,$A15,'Assessment Sheet'!$O$2:$O$241,"<="&VALUE(RIGHT($B$10,1)),'Assessment Sheet'!$K$2:$K$241,"Not applicable") -> 0 | K15: =F15-SUM(G15:J15) -> 18 | L15: =IF(F15-J15=0,"—",G15/(F15-J15)) -> 0 | M15: =IF(COUNTIFS('Assessment Sheet'!$D$2:$D$241,$A15,'Assessment Sheet'!$O$2:$O$241,"<=1",'Assessment Sheet'!$K$2:$K$241,"<>Met",'Assessment Sheet'!$K$2:$K$241,"<>Not applicable")>0,"Below L1",IF(COUNTIFS('Assessment Sheet'!$D$2:$D$241,$A15,'Assessment Sheet'!$O$2:$O$241,"<=2",'Assessment Sheet'!$K$2:$K$241,"<>Met",'Assessment Sheet'!$K$2:$K$241,"<>Not applicable")>0,"L1",IF(COUNTIFS('Assessment Sheet'!$D$2:$D$241,$A15,'Assessment Sheet'!$O$2:$O$241,"<=3",'Assessment Sheet'!$K$2:$K$241,"<>Met",'Assessment Sheet'!$K$2:$K$241,"<>Not applicable")>0,"L2","L3"))) -> Below L1
A16: Harness | B16: =COUNTIFS('Assessment Sheet'!$D$2:$D$241,$A16,'Assessment Sheet'!$F$2:$F$241,"L1") -> 18 | C16: =COUNTIFS('Assessment Sheet'!$D$2:$D$241,$A16,'Assessment Sheet'!$F$2:$F$241,"L2") -> 28 | D16: =COUNTIFS('Assessment Sheet'!$D$2:$D$241,$A16,'Assessment Sheet'!$F$2:$F$241,"L3") -> 2 | E16: =SUM(B16:D16) -> 48 | F16: =COUNTIFS('Assessment Sheet'!$D$2:$D$241,$A16,'Assessment Sheet'!$O$2:$O$241,"<="&VALUE(RIGHT($B$10,1))) -> 46 | G16: =COUNTIFS('Assessment Sheet'!$D$2:$D$241,$A16,'Assessment Sheet'!$O$2:$O$241,"<="&VALUE(RIGHT($B$10,1)),'Assessment Sheet'!$K$2:$K$241,"Met") -> 0 | H16: =COUNTIFS('Assessment Sheet'!$D$2:$D$241,$A16,'Assessment Sheet'!$O$2:$O$241,"<="&VALUE(RIGHT($B$10,1)),'Assessment Sheet'!$K$2:$K$241,"Partially Met") -> 0 | I16: =COUNTIFS('Assessment Sheet'!$D$2:$D$241,$A16,'Assessment Sheet'!$O$2:$O$241,"<="&VALUE(RIGHT($B$10,1)),'Assessment Sheet'!$K$2:$K$241,"Unmet") -> 0 | J16: =COUNTIFS('Assessment Sheet'!$D$2:$D$241,$A16,'Assessment Sheet'!$O$2:$O$241,"<="&VALUE(RIGHT($B$10,1)),'Assessment Sheet'!$K$2:$K$241,"Not applicable") -> 0 | K16: =F16-SUM(G16:J16) -> 46 | L16: =IF(F16-J16=0,"—",G16/(F16-J16)) -> 0 | M16: =IF(COUNTIFS('Assessment Sheet'!$D$2:$D$241,$A16,'Assessment Sheet'!$O$2:$O$241,"<=1",'Assessment Sheet'!$K$2:$K$241,"<>Met",'Assessment Sheet'!$K$2:$K$241,"<>Not applicable")>0,"Below L1",IF(COUNTIFS('Assessment Sheet'!$D$2:$D$241,$A16,'Assessment Sheet'!$O$2:$O$241,"<=2",'Assessment Sheet'!$K$2:$K$241,"<>Met",'Assessment Sheet'!$K$2:$K$241,"<>Not applicable")>0,"L1",IF(COUNTIFS('Assessment Sheet'!$D$2:$D$241,$A16,'Assessment Sheet'!$O$2:$O$241,"<=3",'Assessment Sheet'!$K$2:$K$241,"<>Met",'Assessment Sheet'!$K$2:$K$241,"<>Not applicable")>0,"L2","L3"))) -> Below L1
A17: Policy decision point | B17: =COUNTIFS('Assessment Sheet'!$D$2:$D$241,$A17,'Assessment Sheet'!$F$2:$F$241,"L1") -> 12 | C17: =COUNTIFS('Assessment Sheet'!$D$2:$D$241,$A17,'Assessment Sheet'!$F$2:$F$241,"L2") -> 12 | D17: =COUNTIFS('Assessment Sheet'!$D$2:$D$241,$A17,'Assessment Sheet'!$F$2:$F$241,"L3") -> 5 | E17: =SUM(B17:D17) -> 29 | F17: =COUNTIFS('Assessment Sheet'!$D$2:$D$241,$A17,'Assessment Sheet'!$O$2:$O$241,"<="&VALUE(RIGHT($B$10,1))) -> 24 | G17: =COUNTIFS('Assessment Sheet'!$D$2:$D$241,$A17,'Assessment Sheet'!$O$2:$O$241,"<="&VALUE(RIGHT($B$10,1)),'Assessment Sheet'!$K$2:$K$241,"Met") -> 0 | H17: =COUNTIFS('Assessment Sheet'!$D$2:$D$241,$A17,'Assessment Sheet'!$O$2:$O$241,"<="&VALUE(RIGHT($B$10,1)),'Assessment Sheet'!$K$2:$K$241,"Partially Met") -> 0 | I17: =COUNTIFS('Assessment Sheet'!$D$2:$D$241,$A17,'Assessment Sheet'!$O$2:$O$241,"<="&VALUE(RIGHT($B$10,1)),'Assessment Sheet'!$K$2:$K$241,"Unmet") -> 0 | J17: =COUNTIFS('Assessment Sheet'!$D$2:$D$241,$A17,'Assessment Sheet'!$O$2:$O$241,"<="&VALUE(RIGHT($B$10,1)),'Assessment Sheet'!$K$2:$K$241,"Not applicable") -> 0 | K17: =F17-SUM(G17:J17) -> 24 | L17: =IF(F17-J17=0,"—",G17/(F17-J17)) -> 0 | M17: =IF(COUNTIFS('Assessment Sheet'!$D$2:$D$241,$A17,'Assessment Sheet'!$O$2:$O$241,"<=1",'Assessment Sheet'!$K$2:$K$241,"<>Met",'Assessment Sheet'!$K$2:$K$241,"<>Not applicable")>0,"Below L1",IF(COUNTIFS('Assessment Sheet'!$D$2:$D$241,$A17,'Assessment Sheet'!$O$2:$O$241,"<=2",'Assessment Sheet'!$K$2:$K$241,"<>Met",'Assessment Sheet'!$K$2:$K$241,"<>Not applicable")>0,"L1",IF(COUNTIFS('Assessment Sheet'!$D$2:$D$241,$A17,'Assessment Sheet'!$O$2:$O$241,"<=3",'Assessment Sheet'!$K$2:$K$241,"<>Met",'Assessment Sheet'!$K$2:$K$241,"<>Not applicable")>0,"L2","L3"))) -> Below L1
A18: Egress gateway | B18: =COUNTIFS('Assessment Sheet'!$D$2:$D$241,$A18,'Assessment Sheet'!$F$2:$F$241,"L1") -> 16 | C18: =COUNTIFS('Assessment Sheet'!$D$2:$D$241,$A18,'Assessment Sheet'!$F$2:$F$241,"L2") -> 16 | D18: =COUNTIFS('Assessment Sheet'!$D$2:$D$241,$A18,'Assessment Sheet'!$F$2:$F$241,"L3") -> 0 | E18: =SUM(B18:D18) -> 32 | F18: =COUNTIFS('Assessment Sheet'!$D$2:$D$241,$A18,'Assessment Sheet'!$O$2:$O$241,"<="&VALUE(RIGHT($B$10,1))) -> 32 | G18: =COUNTIFS('Assessment Sheet'!$D$2:$D$241,$A18,'Assessment Sheet'!$O$2:$O$241,"<="&VALUE(RIGHT($B$10,1)),'Assessment Sheet'!$K$2:$K$241,"Met") -> 0 | H18: =COUNTIFS('Assessment Sheet'!$D$2:$D$241,$A18,'Assessment Sheet'!$O$2:$O$241,"<="&VALUE(RIGHT($B$10,1)),'Assessment Sheet'!$K$2:$K$241,"Partially Met") -> 0 | I18: =COUNTIFS('Assessment Sheet'!$D$2:$D$241,$A18,'Assessment Sheet'!$O$2:$O$241,"<="&VALUE(RIGHT($B$10,1)),'Assessment Sheet'!$K$2:$K$241,"Unmet") -> 0 | J18: =COUNTIFS('Assessment Sheet'!$D$2:$D$241,$A18,'Assessment Sheet'!$O$2:$O$241,"<="&VALUE(RIGHT($B$10,1)),'Assessment Sheet'!$K$2:$K$241,"Not applicable") -> 0 | K18: =F18-SUM(G18:J18) -> 32 | L18: =IF(F18-J18=0,"—",G18/(F18-J18)) -> 0 | M18: =IF(COUNTIFS('Assessment Sheet'!$D$2:$D$241,$A18,'Assessment Sheet'!$O$2:$O$241,"<=1",'Assessment Sheet'!$K$2:$K$241,"<>Met",'Assessment Sheet'!$K$2:$K$241,"<>Not applicable")>0,"Below L1",IF(COUNTIFS('Assessment Sheet'!$D$2:$D$241,$A18,'Assessment Sheet'!$O$2:$O$241,"<=2",'Assessment Sheet'!$K$2:$K$241,"<>Met",'Assessment Sheet'!$K$2:$K$241,"<>Not applicable")>0,"L1",IF(COUNTIFS('Assessment Sheet'!$D$2:$D$241,$A18,'Assessment Sheet'!$O$2:$O$241,"<=3",'Assessment Sheet'!$K$2:$K$241,"<>Met",'Assessment Sheet'!$K$2:$K$241,"<>Not applicable")>0,"L2","L3"))) -> Below L1
A19: Downstream systems | B19: =COUNTIFS('Assessment Sheet'!$D$2:$D$241,$A19,'Assessment Sheet'!$F$2:$F$241,"L1") -> 2 | C19: =COUNTIFS('Assessment Sheet'!$D$2:$D$241,$A19,'Assessment Sheet'!$F$2:$F$241,"L2") -> 2 | D19: =COUNTIFS('Assessment Sheet'!$D$2:$D$241,$A19,'Assessment Sheet'!$F$2:$F$241,"L3") -> 0 | E19: =SUM(B19:D19) -> 4 | F19: =COUNTIFS('Assessment Sheet'!$D$2:$D$241,$A19,'Assessment Sheet'!$O$2:$O$241,"<="&VALUE(RIGHT($B$10,1))) -> 4 | G19: =COUNTIFS('Assessment Sheet'!$D$2:$D$241,$A19,'Assessment Sheet'!$O$2:$O$241,"<="&VALUE(RIGHT($B$10,1)),'Assessment Sheet'!$K$2:$K$241,"Met") -> 0 | H19: =COUNTIFS('Assessment Sheet'!$D$2:$D$241,$A19,'Assessment Sheet'!$O$2:$O$241,"<="&VALUE(RIGHT($B$10,1)),'Assessment Sheet'!$K$2:$K$241,"Partially Met") -> 0 | I19: =COUNTIFS('Assessment Sheet'!$D$2:$D$241,$A19,'Assessment Sheet'!$O$2:$O$241,"<="&VALUE(RIGHT($B$10,1)),'Assessment Sheet'!$K$2:$K$241,"Unmet") -> 0 | J19: =COUNTIFS('Assessment Sheet'!$D$2:$D$241,$A19,'Assessment Sheet'!$O$2:$O$241,"<="&VALUE(RIGHT($B$10,1)),'Assessment Sheet'!$K$2:$K$241,"Not applicable") -> 0 | K19: =F19-SUM(G19:J19) -> 4 | L19: =IF(F19-J19=0,"—",G19/(F19-J19)) -> 0 | M19: =IF(COUNTIFS('Assessment Sheet'!$D$2:$D$241,$A19,'Assessment Sheet'!$O$2:$O$241,"<=1",'Assessment Sheet'!$K$2:$K$241,"<>Met",'Assessment Sheet'!$K$2:$K$241,"<>Not applicable")>0,"Below L1",IF(COUNTIFS('Assessment Sheet'!$D$2:$D$241,$A19,'Assessment Sheet'!$O$2:$O$241,"<=2",'Assessment Sheet'!$K$2:$K$241,"<>Met",'Assessment Sheet'!$K$2:$K$241,"<>Not applicable")>0,"L1",IF(COUNTIFS('Assessment Sheet'!$D$2:$D$241,$A19,'Assessment Sheet'!$O$2:$O$241,"<=3",'Assessment Sheet'!$K$2:$K$241,"<>Met",'Assessment Sheet'!$K$2:$K$241,"<>Not applicable")>0,"L2","L3"))) -> Below L1
A20: Data layer | B20: =COUNTIFS('Assessment Sheet'!$D$2:$D$241,$A20,'Assessment Sheet'!$F$2:$F$241,"L1") -> 3 | C20: =COUNTIFS('Assessment Sheet'!$D$2:$D$241,$A20,'Assessment Sheet'!$F$2:$F$241,"L2") -> 11 | D20: =COUNTIFS('Assessment Sheet'!$D$2:$D$241,$A20,'Assessment Sheet'!$F$2:$F$241,"L3") -> 0 | E20: =SUM(B20:D20) -> 14 | F20: =COUNTIFS('Assessment Sheet'!$D$2:$D$241,$A20,'Assessment Sheet'!$O$2:$O$241,"<="&VALUE(RIGHT($B$10,1))) -> 14 | G20: =COUNTIFS('Assessment Sheet'!$D$2:$D$241,$A20,'Assessment Sheet'!$O$2:$O$241,"<="&VALUE(RIGHT($B$10,1)),'Assessment Sheet'!$K$2:$K$241,"Met") -> 0 | H20: =COUNTIFS('Assessment Sheet'!$D$2:$D$241,$A20,'Assessment Sheet'!$O$2:$O$241,"<="&VALUE(RIGHT($B$10,1)),'Assessment Sheet'!$K$2:$K$241,"Partially Met") -> 0 | I20: =COUNTIFS('Assessment Sheet'!$D$2:$D$241,$A20,'Assessment Sheet'!$O$2:$O$241,"<="&VALUE(RIGHT($B$10,1)),'Assessment Sheet'!$K$2:$K$241,"Unmet") -> 0 | J20: =COUNTIFS('Assessment Sheet'!$D$2:$D$241,$A20,'Assessment Sheet'!$O$2:$O$241,"<="&VALUE(RIGHT($B$10,1)),'Assessment Sheet'!$K$2:$K$241,"Not applicable") -> 0 | K20: =F20-SUM(G20:J20) -> 14 | L20: =IF(F20-J20=0,"—",G20/(F20-J20)) -> 0 | M20: =IF(COUNTIFS('Assessment Sheet'!$D$2:$D$241,$A20,'Assessment Sheet'!$O$2:$O$241,"<=1",'Assessment Sheet'!$K$2:$K$241,"<>Met",'Assessment Sheet'!$K$2:$K$241,"<>Not applicable")>0,"Below L1",IF(COUNTIFS('Assessment Sheet'!$D$2:$D$241,$A20,'Assessment Sheet'!$O$2:$O$241,"<=2",'Assessment Sheet'!$K$2:$K$241,"<>Met",'Assessment Sheet'!$K$2:$K$241,"<>Not applicable")>0,"L1",IF(COUNTIFS('Assessment Sheet'!$D$2:$D$241,$A20,'Assessment Sheet'!$O$2:$O$241,"<=3",'Assessment Sheet'!$K$2:$K$241,"<>Met",'Assessment Sheet'!$K$2:$K$241,"<>Not applicable")>0,"L2","L3"))) -> Below L1
A21: Execution environment | B21: =COUNTIFS('Assessment Sheet'!$D$2:$D$241,$A21,'Assessment Sheet'!$F$2:$F$241,"L1") -> 7 | C21: =COUNTIFS('Assessment Sheet'!$D$2:$D$241,$A21,'Assessment Sheet'!$F$2:$F$241,"L2") -> 6 | D21: =COUNTIFS('Assessment Sheet'!$D$2:$D$241,$A21,'Assessment Sheet'!$F$2:$F$241,"L3") -> 0 | E21: =SUM(B21:D21) -> 13 | F21: =COUNTIFS('Assessment Sheet'!$D$2:$D$241,$A21,'Assessment Sheet'!$O$2:$O$241,"<="&VALUE(RIGHT($B$10,1))) -> 13 | G21: =COUNTIFS('Assessment Sheet'!$D$2:$D$241,$A21,'Assessment Sheet'!$O$2:$O$241,"<="&VALUE(RIGHT($B$10,1)),'Assessment Sheet'!$K$2:$K$241,"Met") -> 0 | H21: =COUNTIFS('Assessment Sheet'!$D$2:$D$241,$A21,'Assessment Sheet'!$O$2:$O$241,"<="&VALUE(RIGHT($B$10,1)),'Assessment Sheet'!$K$2:$K$241,"Partially Met") -> 0 | I21: =COUNTIFS('Assessment Sheet'!$D$2:$D$241,$A21,'Assessment Sheet'!$O$2:$O$241,"<="&VALUE(RIGHT($B$10,1)),'Assessment Sheet'!$K$2:$K$241,"Unmet") -> 0 | J21: =COUNTIFS('Assessment Sheet'!$D$2:$D$241,$A21,'Assessment Sheet'!$O$2:$O$241,"<="&VALUE(RIGHT($B$10,1)),'Assessment Sheet'!$K$2:$K$241,"Not applicable") -> 0 | K21: =F21-SUM(G21:J21) -> 13 | L21: =IF(F21-J21=0,"—",G21/(F21-J21)) -> 0 | M21: =IF(COUNTIFS('Assessment Sheet'!$D$2:$D$241,$A21,'Assessment Sheet'!$O$2:$O$241,"<=1",'Assessment Sheet'!$K$2:$K$241,"<>Met",'Assessment Sheet'!$K$2:$K$241,"<>Not applicable")>0,"Below L1",IF(COUNTIFS('Assessment Sheet'!$D$2:$D$241,$A21,'Assessment Sheet'!$O$2:$O$241,"<=2",'Assessment Sheet'!$K$2:$K$241,"<>Met",'Assessment Sheet'!$K$2:$K$241,"<>Not applicable")>0,"L1",IF(COUNTIFS('Assessment Sheet'!$D$2:$D$241,$A21,'Assessment Sheet'!$O$2:$O$241,"<=3",'Assessment Sheet'!$K$2:$K$241,"<>Met",'Assessment Sheet'!$K$2:$K$241,"<>Not applicable")>0,"L2","L3"))) -> Below L1
A22: Management plane | B22: =COUNTIFS('Assessment Sheet'!$D$2:$D$241,$A22,'Assessment Sheet'!$F$2:$F$241,"L1") -> 13 | C22: =COUNTIFS('Assessment Sheet'!$D$2:$D$241,$A22,'Assessment Sheet'!$F$2:$F$241,"L2") -> 26 | D22: =COUNTIFS('Assessment Sheet'!$D$2:$D$241,$A22,'Assessment Sheet'!$F$2:$F$241,"L3") -> 1 | E22: =SUM(B22:D22) -> 40 | F22: =COUNTIFS('Assessment Sheet'!$D$2:$D$241,$A22,'Assessment Sheet'!$O$2:$O$241,"<="&VALUE(RIGHT($B$10,1))) -> 39 | G22: =COUNTIFS('Assessment Sheet'!$D$2:$D$241,$A22,'Assessment Sheet'!$O$2:$O$241,"<="&VALUE(RIGHT($B$10,1)),'Assessment Sheet'!$K$2:$K$241,"Met") -> 0 | H22: =COUNTIFS('Assessment Sheet'!$D$2:$D$241,$A22,'Assessment Sheet'!$O$2:$O$241,"<="&VALUE(RIGHT($B$10,1)),'Assessment Sheet'!$K$2:$K$241,"Partially Met") -> 0 | I22: =COUNTIFS('Assessment Sheet'!$D$2:$D$241,$A22,'Assessment Sheet'!$O$2:$O$241,"<="&VALUE(RIGHT($B$10,1)),'Assessment Sheet'!$K$2:$K$241,"Unmet") -> 0 | J22: =COUNTIFS('Assessment Sheet'!$D$2:$D$241,$A22,'Assessment Sheet'!$O$2:$O$241,"<="&VALUE(RIGHT($B$10,1)),'Assessment Sheet'!$K$2:$K$241,"Not applicable") -> 0 | K22: =F22-SUM(G22:J22) -> 39 | L22: =IF(F22-J22=0,"—",G22/(F22-J22)) -> 0 | M22: =IF(COUNTIFS('Assessment Sheet'!$D$2:$D$241,$A22,'Assessment Sheet'!$O$2:$O$241,"<=1",'Assessment Sheet'!$K$2:$K$241,"<>Met",'Assessment Sheet'!$K$2:$K$241,"<>Not applicable")>0,"Below L1",IF(COUNTIFS('Assessment Sheet'!$D$2:$D$241,$A22,'Assessment Sheet'!$O$2:$O$241,"<=2",'Assessment Sheet'!$K$2:$K$241,"<>Met",'Assessment Sheet'!$K$2:$K$241,"<>Not applicable")>0,"L1",IF(COUNTIFS('Assessment Sheet'!$D$2:$D$241,$A22,'Assessment Sheet'!$O$2:$O$241,"<=3",'Assessment Sheet'!$K$2:$K$241,"<>Met",'Assessment Sheet'!$K$2:$K$241,"<>Not applicable")>0,"L2","L3"))) -> Below L1
A23: Audit | B23: =COUNTIFS('Assessment Sheet'!$D$2:$D$241,$A23,'Assessment Sheet'!$F$2:$F$241,"L1") -> 4 | C23: =COUNTIFS('Assessment Sheet'!$D$2:$D$241,$A23,'Assessment Sheet'!$F$2:$F$241,"L2") -> 14 | D23: =COUNTIFS('Assessment Sheet'!$D$2:$D$241,$A23,'Assessment Sheet'!$F$2:$F$241,"L3") -> 2 | E23: =SUM(B23:D23) -> 20 | F23: =COUNTIFS('Assessment Sheet'!$D$2:$D$241,$A23,'Assessment Sheet'!$O$2:$O$241,"<="&VALUE(RIGHT($B$10,1))) -> 18 | G23: =COUNTIFS('Assessment Sheet'!$D$2:$D$241,$A23,'Assessment Sheet'!$O$2:$O$241,"<="&VALUE(RIGHT($B$10,1)),'Assessment Sheet'!$K$2:$K$241,"Met") -> 0 | H23: =COUNTIFS('Assessment Sheet'!$D$2:$D$241,$A23,'Assessment Sheet'!$O$2:$O$241,"<="&VALUE(RIGHT($B$10,1)),'Assessment Sheet'!$K$2:$K$241,"Partially Met") -> 0 | I23: =COUNTIFS('Assessment Sheet'!$D$2:$D$241,$A23,'Assessment Sheet'!$O$2:$O$241,"<="&VALUE(RIGHT($B$10,1)),'Assessment Sheet'!$K$2:$K$241,"Unmet") -> 0 | J23: =COUNTIFS('Assessment Sheet'!$D$2:$D$241,$A23,'Assessment Sheet'!$O$2:$O$241,"<="&VALUE(RIGHT($B$10,1)),'Assessment Sheet'!$K$2:$K$241,"Not applicable") -> 0 | K23: =F23-SUM(G23:J23) -> 18 | L23: =IF(F23-J23=0,"—",G23/(F23-J23)) -> 0 | M23: =IF(COUNTIFS('Assessment Sheet'!$D$2:$D$241,$A23,'Assessment Sheet'!$O$2:$O$241,"<=1",'Assessment Sheet'!$K$2:$K$241,"<>Met",'Assessment Sheet'!$K$2:$K$241,"<>Not applicable")>0,"Below L1",IF(COUNTIFS('Assessment Sheet'!$D$2:$D$241,$A23,'Assessment Sheet'!$O$2:$O$241,"<=2",'Assessment Sheet'!$K$2:$K$241,"<>Met",'Assessment Sheet'!$K$2:$K$241,"<>Not applicable")>0,"L1",IF(COUNTIFS('Assessment Sheet'!$D$2:$D$241,$A23,'Assessment Sheet'!$O$2:$O$241,"<=3",'Assessment Sheet'!$K$2:$K$241,"<>Met",'Assessment Sheet'!$K$2:$K$241,"<>Not applicable")>0,"L2","L3"))) -> Below L1
A24: Total | B24: =SUM(B14:B23) -> 90 | C24: =SUM(C14:C23) -> 137 | D24: =SUM(D14:D23) -> 13 | E24: =SUM(E14:E23) -> 240 | F24: =SUM(F14:F23) -> 227 | G24: =SUM(G14:G23) -> 0 | H24: =SUM(H14:H23) -> 0 | I24: =SUM(I14:I23) -> 0 | ... K24: =SUM(K14:K23) -> 227 | L24: =IF(F24-J24=0,"—",G24/(F24-J24)) -> 0 | M24: =IF(COUNTIFS('Assessment Sheet'!$O$2:$O$241,"<=1",'Assessment Sheet'!$K$2:$K$241,"<>Met",'Assessment Sheet'!$K$2:$K$241,"<>Not applicable")>0,"Below L1",IF(COUNTIFS('Assessment Sheet'!$O$2:$O$241,"<=2",'Assessment Sheet'!$K$2:$K$241,"<>Met",'Assessment Sheet'!$K$2:$K$241,"<>Not applicable")>0,"L1",IF(COUNTIFS('Assessment Sheet'!$O$2:$O$241,"<=3",'Assessment Sheet'!$K$2:$K$241,"<>Met",'Assessment Sheet'!$K$2:$K$241,"<>Not applicable")>0,"L2","L3"))) -> Below L1
A27: By chapter
A28: Chapter | B28: L1 | C28: New in L2 | D28: New in L3 | E28: Total | F28: Items in target | G28: Met | H28: Partially Met | I28: Unmet | J28: Not applicable | K28: Not assessed | L28: Conformance Rate | M28: Achieved Level
A29: V1 Identity and Authentication | B29: =COUNTIFS('Assessment Sheet'!$B$2:$B$241,$A29,'Assessment Sheet'!$F$2:$F$241,"L1") -> 11 | C29: =COUNTIFS('Assessment Sheet'!$B$2:$B$241,$A29,'Assessment Sheet'!$F$2:$F$241,"L2") -> 11 | D29: =COUNTIFS('Assessment Sheet'!$B$2:$B$241,$A29,'Assessment Sheet'!$F$2:$F$241,"L3") -> 1 | E29: =SUM(B29:D29) -> 23 | F29: =COUNTIFS('Assessment Sheet'!$B$2:$B$241,$A29,'Assessment Sheet'!$O$2:$O$241,"<="&VALUE(RIGHT($B$10,1))) -> 22 | G29: =COUNTIFS('Assessment Sheet'!$B$2:$B$241,$A29,'Assessment Sheet'!$O$2:$O$241,"<="&VALUE(RIGHT($B$10,1)),'Assessment Sheet'!$K$2:$K$241,"Met") -> 0 | H29: =COUNTIFS('Assessment Sheet'!$B$2:$B$241,$A29,'Assessment Sheet'!$O$2:$O$241,"<="&VALUE(RIGHT($B$10,1)),'Assessment Sheet'!$K$2:$K$241,"Partially Met") -> 0 | I29: =COUNTIFS('Assessment Sheet'!$B$2:$B$241,$A29,'Assessment Sheet'!$O$2:$O$241,"<="&VALUE(RIGHT($B$10,1)),'Assessment Sheet'!$K$2:$K$241,"Unmet") -> 0 | J29: =COUNTIFS('Assessment Sheet'!$B$2:$B$241,$A29,'Assessment Sheet'!$O$2:$O$241,"<="&VALUE(RIGHT($B$10,1)),'Assessment Sheet'!$K$2:$K$241,"Not applicable") -> 0 | K29: =F29-SUM(G29:J29) -> 22 | L29: =IF(F29-J29=0,"—",G29/(F29-J29)) -> 0 | M29: =IF(COUNTIFS('Assessment Sheet'!$B$2:$B$241,$A29,'Assessment Sheet'!$O$2:$O$241,"<=1",'Assessment Sheet'!$K$2:$K$241,"<>Met",'Assessment Sheet'!$K$2:$K$241,"<>Not applicable")>0,"Below L1",IF(COUNTIFS('Assessment Sheet'!$B$2:$B$241,$A29,'Assessment Sheet'!$O$2:$O$241,"<=2",'Assessment Sheet'!$K$2:$K$241,"<>Met",'Assessment Sheet'!$K$2:$K$241,"<>Not applicable")>0,"L1",IF(COUNTIFS('Assessment Sheet'!$B$2:$B$241,$A29,'Assessment Sheet'!$O$2:$O$241,"<=3",'Assessment Sheet'!$K$2:$K$241,"<>Met",'Assessment Sheet'!$K$2:$K$241,"<>Not applicable")>0,"L2","L3"))) -> Below L1
A30: V2 Delegation and Effective Permissions | B30: =COUNTIFS('Assessment Sheet'!$B$2:$B$241,$A30,'Assessment Sheet'!$F$2:$F$241,"L1") -> 11 | C30: =COUNTIFS('Assessment Sheet'!$B$2:$B$241,$A30,'Assessment Sheet'!$F$2:$F$241,"L2") -> 14 | D30: =COUNTIFS('Assessment Sheet'!$B$2:$B$241,$A30,'Assessment Sheet'!$F$2:$F$241,"L3") -> 3 | E30: =SUM(B30:D30) -> 28 | F30: =COUNTIFS('Assessment Sheet'!$B$2:$B$241,$A30,'Assessment Sheet'!$O$2:$O$241,"<="&VALUE(RIGHT($B$10,1))) -> 25 | G30: =COUNTIFS('Assessment Sheet'!$B$2:$B$241,$A30,'Assessment Sheet'!$O$2:$O$241,"<="&VALUE(RIGHT($B$10,1)),'Assessment Sheet'!$K$2:$K$241,"Met") -> 0 | H30: =COUNTIFS('Assessment Sheet'!$B$2:$B$241,$A30,'Assessment Sheet'!$O$2:$O$241,"<="&VALUE(RIGHT($B$10,1)),'Assessment Sheet'!$K$2:$K$241,"Partially Met") -> 0 | I30: =COUNTIFS('Assessment Sheet'!$B$2:$B$241,$A30,'Assessment Sheet'!$O$2:$O$241,"<="&VALUE(RIGHT($B$10,1)),'Assessment Sheet'!$K$2:$K$241,"Unmet") -> 0 | J30: =COUNTIFS('Assessment Sheet'!$B$2:$B$241,$A30,'Assessment Sheet'!$O$2:$O$241,"<="&VALUE(RIGHT($B$10,1)),'Assessment Sheet'!$K$2:$K$241,"Not applicable") -> 0 | K30: =F30-SUM(G30:J30) -> 25 | L30: =IF(F30-J30=0,"—",G30/(F30-J30)) -> 0 | M30: =IF(COUNTIFS('Assessment Sheet'!$B$2:$B$241,$A30,'Assessment Sheet'!$O$2:$O$241,"<=1",'Assessment Sheet'!$K$2:$K$241,"<>Met",'Assessment Sheet'!$K$2:$K$241,"<>Not applicable")>0,"Below L1",IF(COUNTIFS('Assessment Sheet'!$B$2:$B$241,$A30,'Assessment Sheet'!$O$2:$O$241,"<=2",'Assessment Sheet'!$K$2:$K$241,"<>Met",'Assessment Sheet'!$K$2:$K$241,"<>Not applicable")>0,"L1",IF(COUNTIFS('Assessment Sheet'!$B$2:$B$241,$A30,'Assessment Sheet'!$O$2:$O$241,"<=3",'Assessment Sheet'!$K$2:$K$241,"<>Met",'Assessment Sheet'!$K$2:$K$241,"<>Not applicable")>0,"L2","L3"))) -> Below L1
A31: V3 Authorization Decisions | B31: =COUNTIFS('Assessment Sheet'!$B$2:$B$241,$A31,'Assessment Sheet'!$F$2:$F$241,"L1") -> 9 | C31: =COUNTIFS('Assessment Sheet'!$B$2:$B$241,$A31,'Assessment Sheet'!$F$2:$F$241,"L2") -> 16 | D31: =COUNTIFS('Assessment Sheet'!$B$2:$B$241,$A31,'Assessment Sheet'!$F$2:$F$241,"L3") -> 2 | E31: =SUM(B31:D31) -> 27 | F31: =COUNTIFS('Assessment Sheet'!$B$2:$B$241,$A31,'Assessment Sheet'!$O$2:$O$241,"<="&VALUE(RIGHT($B$10,1))) -> 25 | G31: =COUNTIFS('Assessment Sheet'!$B$2:$B$241,$A31,'Assessment Sheet'!$O$2:$O$241,"<="&VALUE(RIGHT($B$10,1)),'Assessment Sheet'!$K$2:$K$241,"Met") -> 0 | H31: =COUNTIFS('Assessment Sheet'!$B$2:$B$241,$A31,'Assessment Sheet'!$O$2:$O$241,"<="&VALUE(RIGHT($B$10,1)),'Assessment Sheet'!$K$2:$K$241,"Partially Met") -> 0 | I31: =COUNTIFS('Assessment Sheet'!$B$2:$B$241,$A31,'Assessment Sheet'!$O$2:$O$241,"<="&VALUE(RIGHT($B$10,1)),'Assessment Sheet'!$K$2:$K$241,"Unmet") -> 0 | J31: =COUNTIFS('Assessment Sheet'!$B$2:$B$241,$A31,'Assessment Sheet'!$O$2:$O$241,"<="&VALUE(RIGHT($B$10,1)),'Assessment Sheet'!$K$2:$K$241,"Not applicable") -> 0 | K31: =F31-SUM(G31:J31) -> 25 | L31: =IF(F31-J31=0,"—",G31/(F31-J31)) -> 0 | M31: =IF(COUNTIFS('Assessment Sheet'!$B$2:$B$241,$A31,'Assessment Sheet'!$O$2:$O$241,"<=1",'Assessment Sheet'!$K$2:$K$241,"<>Met",'Assessment Sheet'!$K$2:$K$241,"<>Not applicable")>0,"Below L1",IF(COUNTIFS('Assessment Sheet'!$B$2:$B$241,$A31,'Assessment Sheet'!$O$2:$O$241,"<=2",'Assessment Sheet'!$K$2:$K$241,"<>Met",'Assessment Sheet'!$K$2:$K$241,"<>Not applicable")>0,"L1",IF(COUNTIFS('Assessment Sheet'!$B$2:$B$241,$A31,'Assessment Sheet'!$O$2:$O$241,"<=3",'Assessment Sheet'!$K$2:$K$241,"<>Met",'Assessment Sheet'!$K$2:$K$241,"<>Not applicable")>0,"L2","L3"))) -> Below L1
A32: V4 Credentials and Egress Enforcement | B32: =COUNTIFS('Assessment Sheet'!$B$2:$B$241,$A32,'Assessment Sheet'!$F$2:$F$241,"L1") -> 14 | C32: =COUNTIFS('Assessment Sheet'!$B$2:$B$241,$A32,'Assessment Sheet'!$F$2:$F$241,"L2") -> 18 | D32: =COUNTIFS('Assessment Sheet'!$B$2:$B$241,$A32,'Assessment Sheet'!$F$2:$F$241,"L3") -> 1 | E32: =SUM(B32:D32) -> 33 | F32: =COUNTIFS('Assessment Sheet'!$B$2:$B$241,$A32,'Assessment Sheet'!$O$2:$O$241,"<="&VALUE(RIGHT($B$10,1))) -> 32 | G32: =COUNTIFS('Assessment Sheet'!$B$2:$B$241,$A32,'Assessment Sheet'!$O$2:$O$241,"<="&VALUE(RIGHT($B$10,1)),'Assessment Sheet'!$K$2:$K$241,"Met") -> 0 | H32: =COUNTIFS('Assessment Sheet'!$B$2:$B$241,$A32,'Assessment Sheet'!$O$2:$O$241,"<="&VALUE(RIGHT($B$10,1)),'Assessment Sheet'!$K$2:$K$241,"Partially Met") -> 0 | I32: =COUNTIFS('Assessment Sheet'!$B$2:$B$241,$A32,'Assessment Sheet'!$O$2:$O$241,"<="&VALUE(RIGHT($B$10,1)),'Assessment Sheet'!$K$2:$K$241,"Unmet") -> 0 | J32: =COUNTIFS('Assessment Sheet'!$B$2:$B$241,$A32,'Assessment Sheet'!$O$2:$O$241,"<="&VALUE(RIGHT($B$10,1)),'Assessment Sheet'!$K$2:$K$241,"Not applicable") -> 0 | K32: =F32-SUM(G32:J32) -> 32 | L32: =IF(F32-J32=0,"—",G32/(F32-J32)) -> 0 | M32: =IF(COUNTIFS('Assessment Sheet'!$B$2:$B$241,$A32,'Assessment Sheet'!$O$2:$O$241,"<=1",'Assessment Sheet'!$K$2:$K$241,"<>Met",'Assessment Sheet'!$K$2:$K$241,"<>Not applicable")>0,"Below L1",IF(COUNTIFS('Assessment Sheet'!$B$2:$B$241,$A32,'Assessment Sheet'!$O$2:$O$241,"<=2",'Assessment Sheet'!$K$2:$K$241,"<>Met",'Assessment Sheet'!$K$2:$K$241,"<>Not applicable")>0,"L1",IF(COUNTIFS('Assessment Sheet'!$B$2:$B$241,$A32,'Assessment Sheet'!$O$2:$O$241,"<=3",'Assessment Sheet'!$K$2:$K$241,"<>Met",'Assessment Sheet'!$K$2:$K$241,"<>Not applicable")>0,"L2","L3"))) -> Below L1
A33: V5 Execution Isolation | B33: =COUNTIFS('Assessment Sheet'!$B$2:$B$241,$A33,'Assessment Sheet'!$F$2:$F$241,"L1") -> 16 | C33: =COUNTIFS('Assessment Sheet'!$B$2:$B$241,$A33,'Assessment Sheet'!$F$2:$F$241,"L2") -> 11 | D33: =COUNTIFS('Assessment Sheet'!$B$2:$B$241,$A33,'Assessment Sheet'!$F$2:$F$241,"L3") -> 0 | E33: =SUM(B33:D33) -> 27 | F33: =COUNTIFS('Assessment Sheet'!$B$2:$B$241,$A33,'Assessment Sheet'!$O$2:$O$241,"<="&VALUE(RIGHT($B$10,1))) -> 27 | G33: =COUNTIFS('Assessment Sheet'!$B$2:$B$241,$A33,'Assessment Sheet'!$O$2:$O$241,"<="&VALUE(RIGHT($B$10,1)),'Assessment Sheet'!$K$2:$K$241,"Met") -> 0 | H33: =COUNTIFS('Assessment Sheet'!$B$2:$B$241,$A33,'Assessment Sheet'!$O$2:$O$241,"<="&VALUE(RIGHT($B$10,1)),'Assessment Sheet'!$K$2:$K$241,"Partially Met") -> 0 | I33: =COUNTIFS('Assessment Sheet'!$B$2:$B$241,$A33,'Assessment Sheet'!$O$2:$O$241,"<="&VALUE(RIGHT($B$10,1)),'Assessment Sheet'!$K$2:$K$241,"Unmet") -> 0 | J33: =COUNTIFS('Assessment Sheet'!$B$2:$B$241,$A33,'Assessment Sheet'!$O$2:$O$241,"<="&VALUE(RIGHT($B$10,1)),'Assessment Sheet'!$K$2:$K$241,"Not applicable") -> 0 | K33: =F33-SUM(G33:J33) -> 27 | L33: =IF(F33-J33=0,"—",G33/(F33-J33)) -> 0 | M33: =IF(COUNTIFS('Assessment Sheet'!$B$2:$B$241,$A33,'Assessment Sheet'!$O$2:$O$241,"<=1",'Assessment Sheet'!$K$2:$K$241,"<>Met",'Assessment Sheet'!$K$2:$K$241,"<>Not applicable")>0,"Below L1",IF(COUNTIFS('Assessment Sheet'!$B$2:$B$241,$A33,'Assessment Sheet'!$O$2:$O$241,"<=2",'Assessment Sheet'!$K$2:$K$241,"<>Met",'Assessment Sheet'!$K$2:$K$241,"<>Not applicable")>0,"L1",IF(COUNTIFS('Assessment Sheet'!$B$2:$B$241,$A33,'Assessment Sheet'!$O$2:$O$241,"<=3",'Assessment Sheet'!$K$2:$K$241,"<>Met",'Assessment Sheet'!$K$2:$K$241,"<>Not applicable")>0,"L2","L3"))) -> Below L1
A34: V6 Context and Untrusted Input | B34: =COUNTIFS('Assessment Sheet'!$B$2:$B$241,$A34,'Assessment Sheet'!$F$2:$F$241,"L1") -> 4 | C34: =COUNTIFS('Assessment Sheet'!$B$2:$B$241,$A34,'Assessment Sheet'!$F$2:$F$241,"L2") -> 8 | D34: =COUNTIFS('Assessment Sheet'!$B$2:$B$241,$A34,'Assessment Sheet'!$F$2:$F$241,"L3") -> 1 | E34: =SUM(B34:D34) -> 13 | F34: =COUNTIFS('Assessment Sheet'!$B$2:$B$241,$A34,'Assessment Sheet'!$O$2:$O$241,"<="&VALUE(RIGHT($B$10,1))) -> 12 | G34: =COUNTIFS('Assessment Sheet'!$B$2:$B$241,$A34,'Assessment Sheet'!$O$2:$O$241,"<="&VALUE(RIGHT($B$10,1)),'Assessment Sheet'!$K$2:$K$241,"Met") -> 0 | H34: =COUNTIFS('Assessment Sheet'!$B$2:$B$241,$A34,'Assessment Sheet'!$O$2:$O$241,"<="&VALUE(RIGHT($B$10,1)),'Assessment Sheet'!$K$2:$K$241,"Partially Met") -> 0 | I34: =COUNTIFS('Assessment Sheet'!$B$2:$B$241,$A34,'Assessment Sheet'!$O$2:$O$241,"<="&VALUE(RIGHT($B$10,1)),'Assessment Sheet'!$K$2:$K$241,"Unmet") -> 0 | J34: =COUNTIFS('Assessment Sheet'!$B$2:$B$241,$A34,'Assessment Sheet'!$O$2:$O$241,"<="&VALUE(RIGHT($B$10,1)),'Assessment Sheet'!$K$2:$K$241,"Not applicable") -> 0 | K34: =F34-SUM(G34:J34) -> 12 | L34: =IF(F34-J34=0,"—",G34/(F34-J34)) -> 0 | M34: =IF(COUNTIFS('Assessment Sheet'!$B$2:$B$241,$A34,'Assessment Sheet'!$O$2:$O$241,"<=1",'Assessment Sheet'!$K$2:$K$241,"<>Met",'Assessment Sheet'!$K$2:$K$241,"<>Not applicable")>0,"Below L1",IF(COUNTIFS('Assessment Sheet'!$B$2:$B$241,$A34,'Assessment Sheet'!$O$2:$O$241,"<=2",'Assessment Sheet'!$K$2:$K$241,"<>Met",'Assessment Sheet'!$K$2:$K$241,"<>Not applicable")>0,"L1",IF(COUNTIFS('Assessment Sheet'!$B$2:$B$241,$A34,'Assessment Sheet'!$O$2:$O$241,"<=3",'Assessment Sheet'!$K$2:$K$241,"<>Met",'Assessment Sheet'!$K$2:$K$241,"<>Not applicable")>0,"L2","L3"))) -> Below L1
A35: V7 Output and Visibility | B35: =COUNTIFS('Assessment Sheet'!$B$2:$B$241,$A35,'Assessment Sheet'!$F$2:$F$241,"L1") -> 6 | C35: =COUNTIFS('Assessment Sheet'!$B$2:$B$241,$A35,'Assessment Sheet'!$F$2:$F$241,"L2") -> 12 | D35: =COUNTIFS('Assessment Sheet'!$B$2:$B$241,$A35,'Assessment Sheet'!$F$2:$F$241,"L3") -> 0 | E35: =SUM(B35:D35) -> 18 | F35: =COUNTIFS('Assessment Sheet'!$B$2:$B$241,$A35,'Assessment Sheet'!$O$2:$O$241,"<="&VALUE(RIGHT($B$10,1))) -> 18 | G35: =COUNTIFS('Assessment Sheet'!$B$2:$B$241,$A35,'Assessment Sheet'!$O$2:$O$241,"<="&VALUE(RIGHT($B$10,1)),'Assessment Sheet'!$K$2:$K$241,"Met") -> 0 | H35: =COUNTIFS('Assessment Sheet'!$B$2:$B$241,$A35,'Assessment Sheet'!$O$2:$O$241,"<="&VALUE(RIGHT($B$10,1)),'Assessment Sheet'!$K$2:$K$241,"Partially Met") -> 0 | I35: =COUNTIFS('Assessment Sheet'!$B$2:$B$241,$A35,'Assessment Sheet'!$O$2:$O$241,"<="&VALUE(RIGHT($B$10,1)),'Assessment Sheet'!$K$2:$K$241,"Unmet") -> 0 | J35: =COUNTIFS('Assessment Sheet'!$B$2:$B$241,$A35,'Assessment Sheet'!$O$2:$O$241,"<="&VALUE(RIGHT($B$10,1)),'Assessment Sheet'!$K$2:$K$241,"Not applicable") -> 0 | K35: =F35-SUM(G35:J35) -> 18 | L35: =IF(F35-J35=0,"—",G35/(F35-J35)) -> 0 | M35: =IF(COUNTIFS('Assessment Sheet'!$B$2:$B$241,$A35,'Assessment Sheet'!$O$2:$O$241,"<=1",'Assessment Sheet'!$K$2:$K$241,"<>Met",'Assessment Sheet'!$K$2:$K$241,"<>Not applicable")>0,"Below L1",IF(COUNTIFS('Assessment Sheet'!$B$2:$B$241,$A35,'Assessment Sheet'!$O$2:$O$241,"<=2",'Assessment Sheet'!$K$2:$K$241,"<>Met",'Assessment Sheet'!$K$2:$K$241,"<>Not applicable")>0,"L1",IF(COUNTIFS('Assessment Sheet'!$B$2:$B$241,$A35,'Assessment Sheet'!$O$2:$O$241,"<=3",'Assessment Sheet'!$K$2:$K$241,"<>Met",'Assessment Sheet'!$K$2:$K$241,"<>Not applicable")>0,"L2","L3"))) -> Below L1
A36: V8 Data, Memory, and Output Artifacts | B36: =COUNTIFS('Assessment Sheet'!$B$2:$B$241,$A36,'Assessment Sheet'!$F$2:$F$241,"L1") -> 5 | C36: =COUNTIFS('Assessment Sheet'!$B$2:$B$241,$A36,'Assessment Sheet'!$F$2:$F$241,"L2") -> 16 | D36: =COUNTIFS('Assessment Sheet'!$B$2:$B$241,$A36,'Assessment Sheet'!$F$2:$F$241,"L3") -> 1 | E36: =SUM(B36:D36) -> 22 | F36: =COUNTIFS('Assessment Sheet'!$B$2:$B$241,$A36,'Assessment Sheet'!$O$2:$O$241,"<="&VALUE(RIGHT($B$10,1))) -> 21 | G36: =COUNTIFS('Assessment Sheet'!$B$2:$B$241,$A36,'Assessment Sheet'!$O$2:$O$241,"<="&VALUE(RIGHT($B$10,1)),'Assessment Sheet'!$K$2:$K$241,"Met") -> 0 | H36: =COUNTIFS('Assessment Sheet'!$B$2:$B$241,$A36,'Assessment Sheet'!$O$2:$O$241,"<="&VALUE(RIGHT($B$10,1)),'Assessment Sheet'!$K$2:$K$241,"Partially Met") -> 0 | I36: =COUNTIFS('Assessment Sheet'!$B$2:$B$241,$A36,'Assessment Sheet'!$O$2:$O$241,"<="&VALUE(RIGHT($B$10,1)),'Assessment Sheet'!$K$2:$K$241,"Unmet") -> 0 | J36: =COUNTIFS('Assessment Sheet'!$B$2:$B$241,$A36,'Assessment Sheet'!$O$2:$O$241,"<="&VALUE(RIGHT($B$10,1)),'Assessment Sheet'!$K$2:$K$241,"Not applicable") -> 0 | K36: =F36-SUM(G36:J36) -> 21 | L36: =IF(F36-J36=0,"—",G36/(F36-J36)) -> 0 | M36: =IF(COUNTIFS('Assessment Sheet'!$B$2:$B$241,$A36,'Assessment Sheet'!$O$2:$O$241,"<=1",'Assessment Sheet'!$K$2:$K$241,"<>Met",'Assessment Sheet'!$K$2:$K$241,"<>Not applicable")>0,"Below L1",IF(COUNTIFS('Assessment Sheet'!$B$2:$B$241,$A36,'Assessment Sheet'!$O$2:$O$241,"<=2",'Assessment Sheet'!$K$2:$K$241,"<>Met",'Assessment Sheet'!$K$2:$K$241,"<>Not applicable")>0,"L1",IF(COUNTIFS('Assessment Sheet'!$B$2:$B$241,$A36,'Assessment Sheet'!$O$2:$O$241,"<=3",'Assessment Sheet'!$K$2:$K$241,"<>Met",'Assessment Sheet'!$K$2:$K$241,"<>Not applicable")>0,"L2","L3"))) -> Below L1
A37: V9 Lifecycle and Governance | B37: =COUNTIFS('Assessment Sheet'!$B$2:$B$241,$A37,'Assessment Sheet'!$F$2:$F$241,"L1") -> 9 | C37: =COUNTIFS('Assessment Sheet'!$B$2:$B$241,$A37,'Assessment Sheet'!$F$2:$F$241,"L2") -> 16 | D37: =COUNTIFS('Assessment Sheet'!$B$2:$B$241,$A37,'Assessment Sheet'!$F$2:$F$241,"L3") -> 1 | E37: =SUM(B37:D37) -> 26 | F37: =COUNTIFS('Assessment Sheet'!$B$2:$B$241,$A37,'Assessment Sheet'!$O$2:$O$241,"<="&VALUE(RIGHT($B$10,1))) -> 25 | G37: =COUNTIFS('Assessment Sheet'!$B$2:$B$241,$A37,'Assessment Sheet'!$O$2:$O$241,"<="&VALUE(RIGHT($B$10,1)),'Assessment Sheet'!$K$2:$K$241,"Met") -> 0 | H37: =COUNTIFS('Assessment Sheet'!$B$2:$B$241,$A37,'Assessment Sheet'!$O$2:$O$241,"<="&VALUE(RIGHT($B$10,1)),'Assessment Sheet'!$K$2:$K$241,"Partially Met") -> 0 | I37: =COUNTIFS('Assessment Sheet'!$B$2:$B$241,$A37,'Assessment Sheet'!$O$2:$O$241,"<="&VALUE(RIGHT($B$10,1)),'Assessment Sheet'!$K$2:$K$241,"Unmet") -> 0 | J37: =COUNTIFS('Assessment Sheet'!$B$2:$B$241,$A37,'Assessment Sheet'!$O$2:$O$241,"<="&VALUE(RIGHT($B$10,1)),'Assessment Sheet'!$K$2:$K$241,"Not applicable") -> 0 | K37: =F37-SUM(G37:J37) -> 25 | L37: =IF(F37-J37=0,"—",G37/(F37-J37)) -> 0 | M37: =IF(COUNTIFS('Assessment Sheet'!$B$2:$B$241,$A37,'Assessment Sheet'!$O$2:$O$241,"<=1",'Assessment Sheet'!$K$2:$K$241,"<>Met",'Assessment Sheet'!$K$2:$K$241,"<>Not applicable")>0,"Below L1",IF(COUNTIFS('Assessment Sheet'!$B$2:$B$241,$A37,'Assessment Sheet'!$O$2:$O$241,"<=2",'Assessment Sheet'!$K$2:$K$241,"<>Met",'Assessment Sheet'!$K$2:$K$241,"<>Not applicable")>0,"L1",IF(COUNTIFS('Assessment Sheet'!$B$2:$B$241,$A37,'Assessment Sheet'!$O$2:$O$241,"<=3",'Assessment Sheet'!$K$2:$K$241,"<>Met",'Assessment Sheet'!$K$2:$K$241,"<>Not applicable")>0,"L2","L3"))) -> Below L1
A38: V10 Audit, Detection, and Response | B38: =COUNTIFS('Assessment Sheet'!$B$2:$B$241,$A38,'Assessment Sheet'!$F$2:$F$241,"L1") -> 5 | C38: =COUNTIFS('Assessment Sheet'!$B$2:$B$241,$A38,'Assessment Sheet'!$F$2:$F$241,"L2") -> 15 | D38: =COUNTIFS('Assessment Sheet'!$B$2:$B$241,$A38,'Assessment Sheet'!$F$2:$F$241,"L3") -> 3 | E38: =SUM(B38:D38) -> 23 | F38: =COUNTIFS('Assessment Sheet'!$B$2:$B$241,$A38,'Assessment Sheet'!$O$2:$O$241,"<="&VALUE(RIGHT($B$10,1))) -> 20 | G38: =COUNTIFS('Assessment Sheet'!$B$2:$B$241,$A38,'Assessment Sheet'!$O$2:$O$241,"<="&VALUE(RIGHT($B$10,1)),'Assessment Sheet'!$K$2:$K$241,"Met") -> 0 | H38: =COUNTIFS('Assessment Sheet'!$B$2:$B$241,$A38,'Assessment Sheet'!$O$2:$O$241,"<="&VALUE(RIGHT($B$10,1)),'Assessment Sheet'!$K$2:$K$241,"Partially Met") -> 0 | I38: =COUNTIFS('Assessment Sheet'!$B$2:$B$241,$A38,'Assessment Sheet'!$O$2:$O$241,"<="&VALUE(RIGHT($B$10,1)),'Assessment Sheet'!$K$2:$K$241,"Unmet") -> 0 | J38: =COUNTIFS('Assessment Sheet'!$B$2:$B$241,$A38,'Assessment Sheet'!$O$2:$O$241,"<="&VALUE(RIGHT($B$10,1)),'Assessment Sheet'!$K$2:$K$241,"Not applicable") -> 0 | K38: =F38-SUM(G38:J38) -> 20 | L38: =IF(F38-J38=0,"—",G38/(F38-J38)) -> 0 | M38: =IF(COUNTIFS('Assessment Sheet'!$B$2:$B$241,$A38,'Assessment Sheet'!$O$2:$O$241,"<=1",'Assessment Sheet'!$K$2:$K$241,"<>Met",'Assessment Sheet'!$K$2:$K$241,"<>Not applicable")>0,"Below L1",IF(COUNTIFS('Assessment Sheet'!$B$2:$B$241,$A38,'Assessment Sheet'!$O$2:$O$241,"<=2",'Assessment Sheet'!$K$2:$K$241,"<>Met",'Assessment Sheet'!$K$2:$K$241,"<>Not applicable")>0,"L1",IF(COUNTIFS('Assessment Sheet'!$B$2:$B$241,$A38,'Assessment Sheet'!$O$2:$O$241,"<=3",'Assessment Sheet'!$K$2:$K$241,"<>Met",'Assessment Sheet'!$K$2:$K$241,"<>Not applicable")>0,"L2","L3"))) -> Below L1
A39: Total | B39: =SUM(B29:B38) -> 90 | C39: =SUM(C29:C38) -> 137 | D39: =SUM(D29:D38) -> 13 | E39: =SUM(E29:E38) -> 240 | F39: =SUM(F29:F38) -> 227 | G39: =SUM(G29:G38) -> 0 | H39: =SUM(H29:H38) -> 0 | I39: =SUM(I29:I38) -> 0 | ... K39: =SUM(K29:K38) -> 227 | L39: =IF(F39-J39=0,"—",G39/(F39-J39)) -> 0 | M39: =IF(COUNTIFS('Assessment Sheet'!$O$2:$O$241,"<=1",'Assessment Sheet'!$K$2:$K$241,"<>Met",'Assessment Sheet'!$K$2:$K$241,"<>Not applicable")>0,"Below L1",IF(COUNTIFS('Assessment Sheet'!$O$2:$O$241,"<=2",'Assessment Sheet'!$K$2:$K$241,"<>Met",'Assessment Sheet'!$K$2:$K$241,"<>Not applicable")>0,"L1",IF(COUNTIFS('Assessment Sheet'!$O$2:$O$241,"<=3",'Assessment Sheet'!$K$2:$K$241,"<>Met",'Assessment Sheet'!$K$2:$K$241,"<>Not applicable")>0,"L2","L3"))) -> Below L1
A42: Component × Chapter (item counts across all levels)
A43: Component | B43: V1 | C43: V2 | D43: V3 | E43: V4 | F43: V5 | G43: V6 | H43: V7 | I43: V8 | J43: V9 | K43: V10 | L43: Total
A44: Identity layer | B44: =COUNTIFS('Assessment Sheet'!$D$2:$D$241,$A44,'Assessment Sheet'!$B$2:$B$241,"V1 Identity and Authentication") -> 12 | C44: =COUNTIFS('Assessment Sheet'!$D$2:$D$241,$A44,'Assessment Sheet'!$B$2:$B$241,"V2 Delegation and Effective Permissions") -> 3 | D44: =COUNTIFS('Assessment Sheet'!$D$2:$D$241,$A44,'Assessment Sheet'!$B$2:$B$241,"V3 Authorization Decisions") -> 1 | E44: =COUNTIFS('Assessment Sheet'!$D$2:$D$241,$A44,'Assessment Sheet'!$B$2:$B$241,"V4 Credentials and Egress Enforcement") -> 4 | F44: =COUNTIFS('Assessment Sheet'!$D$2:$D$241,$A44,'Assessment Sheet'!$B$2:$B$241,"V5 Execution Isolation") -> 1 | G44: =COUNTIFS('Assessment Sheet'!$D$2:$D$241,$A44,'Assessment Sheet'!$B$2:$B$241,"V6 Context and Untrusted Input") -> 0 | H44: =COUNTIFS('Assessment Sheet'!$D$2:$D$241,$A44,'Assessment Sheet'!$B$2:$B$241,"V7 Output and Visibility") -> 0 | I44: =COUNTIFS('Assessment Sheet'!$D$2:$D$241,$A44,'Assessment Sheet'!$B$2:$B$241,"V8 Data, Memory, and Output Artifacts") -> 0 | J44: =COUNTIFS('Assessment Sheet'!$D$2:$D$241,$A44,'Assessment Sheet'!$B$2:$B$241,"V9 Lifecycle and Governance") -> 1 | K44: =COUNTIFS('Assessment Sheet'!$D$2:$D$241,$A44,'Assessment Sheet'!$B$2:$B$241,"V10 Audit, Detection, and Response") -> 0 | L44: =SUM(B44:K44) -> 22
A45: Interaction channel | B45: =COUNTIFS('Assessment Sheet'!$D$2:$D$241,$A45,'Assessment Sheet'!$B$2:$B$241,"V1 Identity and Authentication") -> 6 | C45: =COUNTIFS('Assessment Sheet'!$D$2:$D$241,$A45,'Assessment Sheet'!$B$2:$B$241,"V2 Delegation and Effective Permissions") -> 1 | D45: =COUNTIFS('Assessment Sheet'!$D$2:$D$241,$A45,'Assessment Sheet'!$B$2:$B$241,"V3 Authorization Decisions") -> 0 | E45: =COUNTIFS('Assessment Sheet'!$D$2:$D$241,$A45,'Assessment Sheet'!$B$2:$B$241,"V4 Credentials and Egress Enforcement") -> 0 | F45: =COUNTIFS('Assessment Sheet'!$D$2:$D$241,$A45,'Assessment Sheet'!$B$2:$B$241,"V5 Execution Isolation") -> 0 | G45: =COUNTIFS('Assessment Sheet'!$D$2:$D$241,$A45,'Assessment Sheet'!$B$2:$B$241,"V6 Context and Untrusted Input") -> 0 | H45: =COUNTIFS('Assessment Sheet'!$D$2:$D$241,$A45,'Assessment Sheet'!$B$2:$B$241,"V7 Output and Visibility") -> 10 | I45: =COUNTIFS('Assessment Sheet'!$D$2:$D$241,$A45,'Assessment Sheet'!$B$2:$B$241,"V8 Data, Memory, and Output Artifacts") -> 1 | J45: =COUNTIFS('Assessment Sheet'!$D$2:$D$241,$A45,'Assessment Sheet'!$B$2:$B$241,"V9 Lifecycle and Governance") -> 0 | K45: =COUNTIFS('Assessment Sheet'!$D$2:$D$241,$A45,'Assessment Sheet'!$B$2:$B$241,"V10 Audit, Detection, and Response") -> 0 | L45: =SUM(B45:K45) -> 18
