Workbook

Sheet 评估表
A1: 编号 | B1: 章 | C1: 小节 | D1: 落点组件 | E1: 要求 | F1: 最低等级 | G1: L1 | H1: L2 | I1: L3 | J1: 适用条件 | K1: 状态 | L1: 证据与说明 | M1: 负责人 | N1: 计划完成 | O1: 等级序号
A2: V1.1.1 | B2: V1 身份与认证 | C2: V1.1 用户认证 | D2: 身份层 | E2: 平台及其全部渠道应只允许通过企业 IdP（OIDC 或 SAML）登录，不提供独立的本地账号，V10.5 规定的紧急访问账号除外 | F2: L1 | G2: ✓ | H2: ✓ | I2: ✓ | J2: 所有平台 | K2: 未评估 | O2: =VALUE(RIGHT(F2,1)) -> 1
A3: V1.1.2 | B3: V1 身份与认证 | C3: V1.1 用户认证 | D3: 身份层 | E3: 应通过 SCIM 或等效机制同步用户和组，IdP 中禁用的用户在平台中同步禁用 | F3: L2 | H3: ✓ | I3: ✓ | J3: 所有平台 | K3: 未评估 | O3: =VALUE(RIGHT(F3,1)) -> 2
A4: V1.1.3 | B4: V1 身份与认证 | C4: V1.1 用户认证 | D4: 身份层 | E4: 应在用户会话中保留 IdP 签发的认证时间和认证强度，供 V3.5 的二次认证判断使用 | F4: L2 | H4: ✓ | I4: ✓ | J4: 所有平台 | K4: 未评估 | O4: =VALUE(RIGHT(F4,1)) -> 2
A5: V1.1.4 | B5: V1 身份与认证 | C5: V1.1 用户认证 | D5: 身份层 | E5: 通过 API 调用 Agent 的凭证（如 API Key、个人访问令牌）应绑定到企业 IdP 中的具体用户或非人类身份，设置到期时间和权限范围，身份禁用时同步失效 | F5: L1 | G5: ✓ | H5: ✓ | I5: ✓ | J5: 所有平台 | K5: 未评估 | O5: =VALUE(RIGHT(F5,1)) -> 1
A6: V1.2.1 | B6: V1 身份与认证 | C6: V1.2 渠道身份映射 | D6: 交互渠道 | E6: 渠道账号应先通过一次 SSO 登录与企业身份绑定，才能调用 Agent | F6: L1 | G6: ✓ | H6: ✓ | I6: ✓ | J6: 支持 IM、邮件、浏览器插件等第三方渠道的平台 | K6: 未评估 | O6: =VALUE(RIGHT(F6,1)) -> 1
A7: V1.2.2 | B7: V1 身份与认证 | C7: V1.2 渠道身份映射 | D7: 交互渠道 | E7: 应以 SSO 绑定结果作为渠道账号的唯一身份依据，不按昵称、显示名或邮箱字符串匹配；邮件渠道按 V1.2.6 执行 | F7: L1 | G7: ✓ | H7: ✓ | I7: ✓ | J7: 支持 IM、邮件、浏览器插件等第三方渠道的平台 | K7: 未评估 | O7: =VALUE(RIGHT(F7,1)) -> 1
A8: V1.2.3 | B8: V1 身份与认证 | C8: V1.2 渠道身份映射 | D8: 交互渠道 | E8: IdP 禁用用户后，该用户的全部渠道绑定应同步失效 | F8: L2 | H8: ✓ | I8: ✓ | J8: 支持 IM、邮件、浏览器插件等第三方渠道的平台 | K8: 未评估 | O8: =VALUE(RIGHT(F8,1)) -> 2
A9: V1.2.4 | B9: V1 身份与认证 | C9: V1.2 渠道身份映射 | D9: 交互渠道 | E9: 应识别外部访客和跨组织共享频道中的账号，并为其单独限定可用的 Agent 和能力 | F9: L2 | H9: ✓ | I9: ✓ | J9: 支持 IM、邮件、浏览器插件等第三方渠道的平台 | K9: 未评估 | O9: =VALUE(RIGHT(F9,1)) -> 2
A10: V1.2.5 | B10: V1 身份与认证 | C10: V1.2 渠道身份映射 | D10: 交互渠道 | E10: 在渠道内触发高风险操作时，应要求用户通过企业 IdP 完成二次认证 | F10: L2 | H10: ✓ | I10: ✓ | J10: 支持 IM、邮件、浏览器插件等第三方渠道的平台 | K10: 未评估 | O10: =VALUE(RIGHT(F10,1)) -> 2
A11: V1.2.6 | B11: V1 身份与认证 | C11: V1.2 渠道身份映射 | D11: 交互渠道 | E11: 邮件渠道应只受理通过 DMARC 校验的邮件（SPF 或 DKIM 通过且与发件域对齐），外部域的发件人不能触发代表用户的操作 | F11: L1 | G11: ✓ | H11: ✓ | I11: ✓ | J11: 支持 IM、邮件、浏览器插件等第三方渠道的平台 | K11: 未评估 | O11: =VALUE(RIGHT(F11,1)) -> 1
A12: V1.3.1 | B12: V1 身份与认证 | C12: V1.3 Agent 身份 | D12: 身份层 | E12: 每个 Agent 应有平台签发的唯一身份标识，不采信 Agent 自报的身份 | F12: L1 | G12: ✓ | H12: ✓ | I12: ✓ | J12: 所有平台 | K12: 未评估 | O12: =VALUE(RIGHT(F12,1)) -> 1
A13: V1.3.2 | B13: V1 身份与认证 | C13: V1.3 Agent 身份 | D13: 身份层 | E13: 应为自主 Agent 在企业目录中建立独立的非人类身份，不使用任何员工的个人账号 | F13: L1 | G13: ✓ | H13: ✓ | I13: ✓ | J13: 所有平台 | K13: 未评估 | O13: =VALUE(RIGHT(F13,1)) -> 1
A14: V1.3.3 | B14: V1 身份与认证 | C14: V1.3 Agent 身份 | D14: 下游系统 | E14: 自主 Agent 访问下游时应使用 V1.3.2 建立的身份，下游日志中记录的主体为该 Agent | F14: L2 | H14: ✓ | I14: ✓ | J14: 所有平台 | K14: 未评估 | O14: =VALUE(RIGHT(F14,1)) -> 2
A15: V1.3.4 | B15: V1 身份与认证 | C15: V1.3 Agent 身份 | D15: 身份层 | E15: 自主 Agent 访问下游应使用短时效令牌，不使用长期静态密钥 | F15: L2 | H15: ✓ | I15: ✓ | J15: 所有平台 | K15: 未评估 | O15: =VALUE(RIGHT(F15,1)) -> 2
A16: V1.3.5 | B16: V1 身份与认证 | C16: V1.3 Agent 身份 | D16: 身份层 | E16: 自主 Agent 的密钥和证书应有签发、轮换和吊销流程，轮换周期设上限 | F16: L2 | H16: ✓ | I16: ✓ | J16: 所有平台 | K16: 未评估 | O16: =VALUE(RIGHT(F16,1)) -> 2
A17: V1.4.1 | B17: V1 身份与认证 | C17: V1.4 工作负载身份 | D17: 身份层 | E17: 平台应为每个会话的执行实例签发短期工作负载身份，并与该实例绑定 | F17: L1 | G17: ✓ | H17: ✓ | I17: ✓ | J17: 为会话分配独立执行实例（如容器、沙箱或虚拟机）的平台 | K17: 未评估 | O17: =VALUE(RIGHT(F17,1)) -> 1
A18: V1.4.2 | B18: V1 身份与认证 | C18: V1.4 工作负载身份 | D18: Harness | E18: 工作负载身份的凭证应对模型不可见，不进入上下文和工具返回 | F18: L1 | G18: ✓ | H18: ✓ | I18: ✓ | J18: 为会话分配独立执行实例（如容器、沙箱或虚拟机）的平台 | K18: 未评估 | O18: =VALUE(RIGHT(F18,1)) -> 1
A19: V1.4.3 | B19: V1 身份与认证 | C19: V1.4 工作负载身份 | D19: 出口网关 | E19: 出口网关应只依据工作负载身份确定用户和 Agent，忽略请求中自报的用户或 Agent 标识 | F19: L1 | G19: ✓ | H19: ✓ | I19: ✓ | J19: 为会话分配独立执行实例（如容器、沙箱或虚拟机）的平台 | K19: 未评估 | O19: =VALUE(RIGHT(F19,1)) -> 1
A20: V1.4.4 | B20: V1 身份与认证 | C20: V1.4 工作负载身份 | D20: 身份层 | E20: 会话结束或执行实例销毁时，应立即吊销对应的工作负载身份 | F20: L2 | H20: ✓ | I20: ✓ | J20: 为会话分配独立执行实例（如容器、沙箱或虚拟机）的平台 | K20: 未评估 | O20: =VALUE(RIGHT(F20,1)) -> 2
A21: V1.4.5 | B21: V1 身份与认证 | C21: V1.4 工作负载身份 | D21: 身份层 | E21: 平台签发工作负载身份前应对执行实例做工作负载证明（如 SPIFFE/SPIRE 的节点证明和工作负载证明），证明失败不签发 | F21: L3 | I21: ✓ | J21: 为会话分配独立执行实例（如容器、沙箱或虚拟机）的平台 | K21: 未评估 | O21: =VALUE(RIGHT(F21,1)) -> 3
A22: V1.5.1 | B22: V1 身份与认证 | C22: V1.5 外部主体 | D22: 身份层 | E22: 应通过身份联邦接入外部主体，不为其创建共享账号 | F22: L2 | H22: ✓ | I22: ✓ | J22: 向客户或合作伙伴开放 Agent 能力的平台 | K22: 未评估 | O22: =VALUE(RIGHT(F22,1)) -> 2
A23: V1.5.2 | B23: V1 身份与认证 | C23: V1.5 外部主体 | D23: 策略决策点 | E23: 外部主体应只能访问为其开放的工作空间和接口 | F23: L1 | G23: ✓ | H23: ✓ | I23: ✓ | J23: 向客户或合作伙伴开放 Agent 能力的平台 | K23: 未评估 | O23: =VALUE(RIGHT(F23,1)) -> 1
A24: V1.5.3 | B24: V1 身份与认证 | C24: V1.5 外部主体 | D24: 审计 | E24: 外部主体的调用应单独记录审计，可按外部组织筛选 | F24: L2 | H24: ✓ | I24: ✓ | J24: 向客户或合作伙伴开放 Agent 能力的平台 | K24: 未评估 | O24: =VALUE(RIGHT(F24,1)) -> 2
A25: V2.1.1 | B25: V2 委托与有效权限 | C25: V2.1 代表用户访问 | D25: 出口网关 | E25: 用户在场时，Agent 访问下游应携带发起用户的身份，由下游按该用户作出授权判定；下游不支持用户级授权判定的按 V4.4 执行 | F25: L1 | G25: ✓ | H25: ✓ | I25: ✓ | J25: 所有平台 | K25: 未评估 | O25: =VALUE(RIGHT(F25,1)) -> 1
A26: V2.1.2 | B26: V2 委托与有效权限 | C26: V2.1 代表用户访问 | D26: 出口网关 | E26: 不应使用权限高于发起用户的共享凭证替用户访问下游，只支持共享静态凭证的下游按 V4.4 执行补偿控制 | F26: L1 | G26: ✓ | H26: ✓ | I26: ✓ | J26: 所有平台 | K26: 未评估 | O26: =VALUE(RIGHT(F26,1)) -> 1
A27: V2.1.3 | B27: V2 委托与有效权限 | C27: V2.1 代表用户访问 | D27: 身份层 | E27: 下游令牌应同时标识发起用户和执行的 Agent（如 RFC 8693 的 act 声明） | F27: L2 | H27: ✓ | I27: ✓ | J27: 所有平台 | K27: 未评估 | O27: =VALUE(RIGHT(F27,1)) -> 2
A28: V2.2.1 | B28: V2 委托与有效权限 | C28: V2.2 有效权限 | D28: 策略决策点 | E28: 每次调用的有效权限应取用户权限与 Agent 授权范围的交集 | F28: L1 | G28: ✓ | H28: ✓ | I28: ✓ | J28: 所有平台 | K28: 未评估 | O28: =VALUE(RIGHT(F28,1)) -> 1
A29: V2.2.2 | B29: V2 委托与有效权限 | C29: V2.2 有效权限 | D29: 策略决策点 | E29: 有效权限应由策略决策点计算，不依赖系统提示词或模型的判断 | F29: L1 | G29: ✓ | H29: ✓ | I29: ✓ | J29: 所有平台 | K29: 未评估 | O29: =VALUE(RIGHT(F29,1)) -> 1
A30: V2.2.3 | B30: V2 委托与有效权限 | C30: V2.2 有效权限 | D30: 策略决策点 | E30: 任务开始时应声明所需的工具和数据范围，运行中只授予声明范围内的权限；声明由用户或 Agent 配置给出，模型提出的范围须经用户确认后生效 | F30: L2 | H30: ✓ | I30: ✓ | J30: 所有平台 | K30: 未评估 | O30: =VALUE(RIGHT(F30,1)) -> 2
A31: V2.2.4 | B31: V2 委托与有效权限 | C31: V2.2 有效权限 | D31: 策略决策点 | E31: 超出任务声明范围的调用应被拒绝或转为审批 | F31: L2 | H31: ✓ | I31: ✓ | J31: 所有平台 | K31: 未评估 | O31: =VALUE(RIGHT(F31,1)) -> 2
A32: V2.2.5 | B32: V2 委托与有效权限 | C32: V2.2 有效权限 | D32: 策略决策点 | E32: 有效权限应在每次工具调用时重新计算，不沿用会话开始时的授权结果 | F32: L2 | H32: ✓ | I32: ✓ | J32: 所有平台 | K32: 未评估 | O32: =VALUE(RIGHT(F32,1)) -> 2
A33: V2.2.6 | B33: V2 委托与有效权限 | C33: V2.2 有效权限 | D33: 策略决策点 | E33: 高风险操作的授权应细化到具体资源和参数（如用 RFC 9396 RAR 描述授权细节），不只授予粗粒度角色 | F33: L3 | I33: ✓ | J33: 所有平台 | K33: 未评估 | O33: =VALUE(RIGHT(F33,1)) -> 3
A34: V2.3.1 | B34: V2 委托与有效权限 | C34: V2.3 离线委托任务 | D34: 策略决策点 | E34: 离线委托任务应以创建用户为根，创建时固定权限上限，之后只能收窄 | F34: L1 | G34: ✓ | H34: ✓ | I34: ✓ | J34: 支持定时任务或长时任务的平台 | K34: 未评估 | O34: =VALUE(RIGHT(F34,1)) -> 1
A35: V2.3.2 | B35: V2 委托与有效权限 | C35: V2.3 离线委托任务 | D35: 策略决策点 | E35: 每次运行前应复查创建用户的账号状态和当前权限 | F35: L1 | G35: ✓ | H35: ✓ | I35: ✓ | J35: 支持定时任务或长时任务的平台 | K35: 未评估 | O35: =VALUE(RIGHT(F35,1)) -> 1
A36: V2.3.3 | B36: V2 委托与有效权限 | C36: V2.3 离线委托任务 | D36: Harness | E36: 调度器应只保存任务标识，不保存用户凭证或可直接使用的令牌 | F36: L1 | G36: ✓ | H36: ✓ | I36: ✓ | J36: 支持定时任务或长时任务的平台 | K36: 未评估 | O36: =VALUE(RIGHT(F36,1)) -> 1
A37: V2.3.4 | B37: V2 委托与有效权限 | C37: V2.3 离线委托任务 | D37: 管理面 | E37: 创建用户被禁用后，其离线委托任务应自动停止并通知该 Agent 的负责人 | F37: L2 | H37: ✓ | I37: ✓ | J37: 支持定时任务或长时任务的平台 | K37: 未评估 | O37: =VALUE(RIGHT(F37,1)) -> 2
A38: V2.3.5 | B38: V2 委托与有效权限 | C38: V2.3 离线委托任务 | D38: 管理面 | E38: 创建用户离职或转岗后仍需继续运行的任务，应在其账号禁用前转为自主 Agent，并重新审批授权 | F38: L2 | H38: ✓ | I38: ✓ | J38: 支持定时任务或长时任务的平台 | K38: 未评估 | O38: =VALUE(RIGHT(F38,1)) -> 2
A39: V2.3.6 | B39: V2 委托与有效权限 | C39: V2.3 离线委托任务 | D39: 策略决策点 | E39: 离线委托任务的授权应设到期时间，到期后需创建用户重新确认 | F39: L2 | H39: ✓ | I39: ✓ | J39: 支持定时任务或长时任务的平台 | K39: 未评估 | O39: =VALUE(RIGHT(F39,1)) -> 2
A40: V2.4.1 | B40: V2 委托与有效权限 | C40: V2.4 Agent 间委托 | D40: 策略决策点 | E40: 下游 Agent 的有效权限不应超过发起用户的权限与上游的委托范围，发起用户不能经由下游 Agent 获得其本人没有的权限 | F40: L1 | G40: ✓ | H40: ✓ | I40: ✓ | J40: 支持多 Agent 协作或子 Agent 的平台 | K40: 未评估 | O40: =VALUE(RIGHT(F40,1)) -> 1
...

Sheet 汇总
A1: 评估进度
A2: 数字由公式从「评估表」实时计算。目标等级内的条目 = 该等级及以下全部条目；满足率 = 已满足 ÷（条目数 − 不适用）；未评估按未满足计。
A4: 目标等级 | B4: 条目数 | C4: 已满足 | D4: 部分满足 | E4: 未满足 | F4: 不适用 | G4: 未评估 | H4: 满足率 | I4: 结论
A5: 达到 L1 | B5: =COUNTIFS('评估表'!$O$2:$O$241,"<=1") -> 90 | C5: =COUNTIFS('评估表'!$O$2:$O$241,"<=1",'评估表'!$K$2:$K$241,"已满足") -> 0 | D5: =COUNTIFS('评估表'!$O$2:$O$241,"<=1",'评估表'!$K$2:$K$241,"部分满足") -> 0 | E5: =COUNTIFS('评估表'!$O$2:$O$241,"<=1",'评估表'!$K$2:$K$241,"未满足") -> 0 | F5: =COUNTIFS('评估表'!$O$2:$O$241,"<=1",'评估表'!$K$2:$K$241,"不适用") -> 0 | G5: =B5-SUM(C5:F5) -> 90 | H5: =IF(B5-F5=0,"—",C5/(B5-F5)) -> 0 | I5: =IF(C5=B5-F5,"已达到","未达到") -> 未达到
A6: 达到 L2 | B6: =COUNTIFS('评估表'!$O$2:$O$241,"<=2") -> 227 | C6: =COUNTIFS('评估表'!$O$2:$O$241,"<=2",'评估表'!$K$2:$K$241,"已满足") -> 0 | D6: =COUNTIFS('评估表'!$O$2:$O$241,"<=2",'评估表'!$K$2:$K$241,"部分满足") -> 0 | E6: =COUNTIFS('评估表'!$O$2:$O$241,"<=2",'评估表'!$K$2:$K$241,"未满足") -> 0 | F6: =COUNTIFS('评估表'!$O$2:$O$241,"<=2",'评估表'!$K$2:$K$241,"不适用") -> 0 | G6: =B6-SUM(C6:F6) -> 227 | H6: =IF(B6-F6=0,"—",C6/(B6-F6)) -> 0 | I6: =IF(C6=B6-F6,"已达到","未达到") -> 未达到
A7: 达到 L3 | B7: =COUNTIFS('评估表'!$O$2:$O$241,"<=3") -> 240 | C7: =COUNTIFS('评估表'!$O$2:$O$241,"<=3",'评估表'!$K$2:$K$241,"已满足") -> 0 | D7: =COUNTIFS('评估表'!$O$2:$O$241,"<=3",'评估表'!$K$2:$K$241,"部分满足") -> 0 | E7: =COUNTIFS('评估表'!$O$2:$O$241,"<=3",'评估表'!$K$2:$K$241,"未满足") -> 0 | F7: =COUNTIFS('评估表'!$O$2:$O$241,"<=3",'评估表'!$K$2:$K$241,"不适用") -> 0 | G7: =B7-SUM(C7:F7) -> 240 | H7: =IF(B7-F7=0,"—",C7/(B7-F7)) -> 0 | I7: =IF(C7=B7-F7,"已达到","未达到") -> 未达到
A10: 下面三张表按此目标等级统计 ▸ | B10: L2 | C10: （下拉切换 L1 / L2 / L3）
A12: 按架构组件
A13: 架构组件 | B13: L1 | C13: L2 新增 | D13: L3 新增 | E13: 合计 | F13: 目标内条目 | G13: 已满足 | H13: 部分满足 | I13: 未满足 | J13: 不适用 | K13: 未评估 | L13: 满足率 | M13: 达成等级
A14: 身份层 | B14: =COUNTIFS('评估表'!$D$2:$D$241,$A14,'评估表'!$F$2:$F$241,"L1") -> 7 | C14: =COUNTIFS('评估表'!$D$2:$D$241,$A14,'评估表'!$F$2:$F$241,"L2") -> 12 | D14: =COUNTIFS('评估表'!$D$2:$D$241,$A14,'评估表'!$F$2:$F$241,"L3") -> 3 | E14: =SUM(B14:D14) -> 22 | F14: =COUNTIFS('评估表'!$D$2:$D$241,$A14,'评估表'!$O$2:$O$241,"<="&VALUE(RIGHT($B$10,1))) -> 19 | G14: =COUNTIFS('评估表'!$D$2:$D$241,$A14,'评估表'!$O$2:$O$241,"<="&VALUE(RIGHT($B$10,1)),'评估表'!$K$2:$K$241,"已满足") -> 0 | H14: =COUNTIFS('评估表'!$D$2:$D$241,$A14,'评估表'!$O$2:$O$241,"<="&VALUE(RIGHT($B$10,1)),'评估表'!$K$2:$K$241,"部分满足") -> 0 | I14: =COUNTIFS('评估表'!$D$2:$D$241,$A14,'评估表'!$O$2:$O$241,"<="&VALUE(RIGHT($B$10,1)),'评估表'!$K$2:$K$241,"未满足") -> 0 | J14: =COUNTIFS('评估表'!$D$2:$D$241,$A14,'评估表'!$O$2:$O$241,"<="&VALUE(RIGHT($B$10,1)),'评估表'!$K$2:$K$241,"不适用") -> 0 | K14: =F14-SUM(G14:J14) -> 19 | L14: =IF(F14-J14=0,"—",G14/(F14-J14)) -> 0 | M14: =IF(COUNTIFS('评估表'!$D$2:$D$241,$A14,'评估表'!$O$2:$O$241,"<=1",'评估表'!$K$2:$K$241,"<>已满足",'评估表'!$K$2:$K$241,"<>不适用")>0,"未达 L1",IF(COUNTIFS('评估表'!$D$2:$D$241,$A14,'评估表'!$O$2:$O$241,"<=2",'评估表'!$K$2:$K$241,"<>已满足",'评估表'!$K$2:$K$241,"<>不适用")>0,"L1",IF(COUNTIFS('评估表'!$D$2:$D$241,$A14,'评估表'!$O$2:$O$241,"<=3",'评估表'!$K$2:$K$241,"<>已满足",'评估表'!$K$2:$K$241,"<>不适用")>0,"L2","L3"))) -> 未达 L1
A15: 交互渠道 | B15: =COUNTIFS('评估表'!$D$2:$D$241,$A15,'评估表'!$F$2:$F$241,"L1") -> 8 | C15: =COUNTIFS('评估表'!$D$2:$D$241,$A15,'评估表'!$F$2:$F$241,"L2") -> 10 | D15: =COUNTIFS('评估表'!$D$2:$D$241,$A15,'评估表'!$F$2:$F$241,"L3") -> 0 | E15: =SUM(B15:D15) -> 18 | F15: =COUNTIFS('评估表'!$D$2:$D$241,$A15,'评估表'!$O$2:$O$241,"<="&VALUE(RIGHT($B$10,1))) -> 18 | G15: =COUNTIFS('评估表'!$D$2:$D$241,$A15,'评估表'!$O$2:$O$241,"<="&VALUE(RIGHT($B$10,1)),'评估表'!$K$2:$K$241,"已满足") -> 0 | H15: =COUNTIFS('评估表'!$D$2:$D$241,$A15,'评估表'!$O$2:$O$241,"<="&VALUE(RIGHT($B$10,1)),'评估表'!$K$2:$K$241,"部分满足") -> 0 | I15: =COUNTIFS('评估表'!$D$2:$D$241,$A15,'评估表'!$O$2:$O$241,"<="&VALUE(RIGHT($B$10,1)),'评估表'!$K$2:$K$241,"未满足") -> 0 | J15: =COUNTIFS('评估表'!$D$2:$D$241,$A15,'评估表'!$O$2:$O$241,"<="&VALUE(RIGHT($B$10,1)),'评估表'!$K$2:$K$241,"不适用") -> 0 | K15: =F15-SUM(G15:J15) -> 18 | L15: =IF(F15-J15=0,"—",G15/(F15-J15)) -> 0 | M15: =IF(COUNTIFS('评估表'!$D$2:$D$241,$A15,'评估表'!$O$2:$O$241,"<=1",'评估表'!$K$2:$K$241,"<>已满足",'评估表'!$K$2:$K$241,"<>不适用")>0,"未达 L1",IF(COUNTIFS('评估表'!$D$2:$D$241,$A15,'评估表'!$O$2:$O$241,"<=2",'评估表'!$K$2:$K$241,"<>已满足",'评估表'!$K$2:$K$241,"<>不适用")>0,"L1",IF(COUNTIFS('评估表'!$D$2:$D$241,$A15,'评估表'!$O$2:$O$241,"<=3",'评估表'!$K$2:$K$241,"<>已满足",'评估表'!$K$2:$K$241,"<>不适用")>0,"L2","L3"))) -> 未达 L1
A16: Harness | B16: =COUNTIFS('评估表'!$D$2:$D$241,$A16,'评估表'!$F$2:$F$241,"L1") -> 18 | C16: =COUNTIFS('评估表'!$D$2:$D$241,$A16,'评估表'!$F$2:$F$241,"L2") -> 28 | D16: =COUNTIFS('评估表'!$D$2:$D$241,$A16,'评估表'!$F$2:$F$241,"L3") -> 2 | E16: =SUM(B16:D16) -> 48 | F16: =COUNTIFS('评估表'!$D$2:$D$241,$A16,'评估表'!$O$2:$O$241,"<="&VALUE(RIGHT($B$10,1))) -> 46 | G16: =COUNTIFS('评估表'!$D$2:$D$241,$A16,'评估表'!$O$2:$O$241,"<="&VALUE(RIGHT($B$10,1)),'评估表'!$K$2:$K$241,"已满足") -> 0 | H16: =COUNTIFS('评估表'!$D$2:$D$241,$A16,'评估表'!$O$2:$O$241,"<="&VALUE(RIGHT($B$10,1)),'评估表'!$K$2:$K$241,"部分满足") -> 0 | I16: =COUNTIFS('评估表'!$D$2:$D$241,$A16,'评估表'!$O$2:$O$241,"<="&VALUE(RIGHT($B$10,1)),'评估表'!$K$2:$K$241,"未满足") -> 0 | J16: =COUNTIFS('评估表'!$D$2:$D$241,$A16,'评估表'!$O$2:$O$241,"<="&VALUE(RIGHT($B$10,1)),'评估表'!$K$2:$K$241,"不适用") -> 0 | K16: =F16-SUM(G16:J16) -> 46 | L16: =IF(F16-J16=0,"—",G16/(F16-J16)) -> 0 | M16: =IF(COUNTIFS('评估表'!$D$2:$D$241,$A16,'评估表'!$O$2:$O$241,"<=1",'评估表'!$K$2:$K$241,"<>已满足",'评估表'!$K$2:$K$241,"<>不适用")>0,"未达 L1",IF(COUNTIFS('评估表'!$D$2:$D$241,$A16,'评估表'!$O$2:$O$241,"<=2",'评估表'!$K$2:$K$241,"<>已满足",'评估表'!$K$2:$K$241,"<>不适用")>0,"L1",IF(COUNTIFS('评估表'!$D$2:$D$241,$A16,'评估表'!$O$2:$O$241,"<=3",'评估表'!$K$2:$K$241,"<>已满足",'评估表'!$K$2:$K$241,"<>不适用")>0,"L2","L3"))) -> 未达 L1
A17: 策略决策点 | B17: =COUNTIFS('评估表'!$D$2:$D$241,$A17,'评估表'!$F$2:$F$241,"L1") -> 12 | C17: =COUNTIFS('评估表'!$D$2:$D$241,$A17,'评估表'!$F$2:$F$241,"L2") -> 12 | D17: =COUNTIFS('评估表'!$D$2:$D$241,$A17,'评估表'!$F$2:$F$241,"L3") -> 5 | E17: =SUM(B17:D17) -> 29 | F17: =COUNTIFS('评估表'!$D$2:$D$241,$A17,'评估表'!$O$2:$O$241,"<="&VALUE(RIGHT($B$10,1))) -> 24 | G17: =COUNTIFS('评估表'!$D$2:$D$241,$A17,'评估表'!$O$2:$O$241,"<="&VALUE(RIGHT($B$10,1)),'评估表'!$K$2:$K$241,"已满足") -> 0 | H17: =COUNTIFS('评估表'!$D$2:$D$241,$A17,'评估表'!$O$2:$O$241,"<="&VALUE(RIGHT($B$10,1)),'评估表'!$K$2:$K$241,"部分满足") -> 0 | I17: =COUNTIFS('评估表'!$D$2:$D$241,$A17,'评估表'!$O$2:$O$241,"<="&VALUE(RIGHT($B$10,1)),'评估表'!$K$2:$K$241,"未满足") -> 0 | J17: =COUNTIFS('评估表'!$D$2:$D$241,$A17,'评估表'!$O$2:$O$241,"<="&VALUE(RIGHT($B$10,1)),'评估表'!$K$2:$K$241,"不适用") -> 0 | K17: =F17-SUM(G17:J17) -> 24 | L17: =IF(F17-J17=0,"—",G17/(F17-J17)) -> 0 | M17: =IF(COUNTIFS('评估表'!$D$2:$D$241,$A17,'评估表'!$O$2:$O$241,"<=1",'评估表'!$K$2:$K$241,"<>已满足",'评估表'!$K$2:$K$241,"<>不适用")>0,"未达 L1",IF(COUNTIFS('评估表'!$D$2:$D$241,$A17,'评估表'!$O$2:$O$241,"<=2",'评估表'!$K$2:$K$241,"<>已满足",'评估表'!$K$2:$K$241,"<>不适用")>0,"L1",IF(COUNTIFS('评估表'!$D$2:$D$241,$A17,'评估表'!$O$2:$O$241,"<=3",'评估表'!$K$2:$K$241,"<>已满足",'评估表'!$K$2:$K$241,"<>不适用")>0,"L2","L3"))) -> 未达 L1
A18: 出口网关 | B18: =COUNTIFS('评估表'!$D$2:$D$241,$A18,'评估表'!$F$2:$F$241,"L1") -> 16 | C18: =COUNTIFS('评估表'!$D$2:$D$241,$A18,'评估表'!$F$2:$F$241,"L2") -> 16 | D18: =COUNTIFS('评估表'!$D$2:$D$241,$A18,'评估表'!$F$2:$F$241,"L3") -> 0 | E18: =SUM(B18:D18) -> 32 | F18: =COUNTIFS('评估表'!$D$2:$D$241,$A18,'评估表'!$O$2:$O$241,"<="&VALUE(RIGHT($B$10,1))) -> 32 | G18: =COUNTIFS('评估表'!$D$2:$D$241,$A18,'评估表'!$O$2:$O$241,"<="&VALUE(RIGHT($B$10,1)),'评估表'!$K$2:$K$241,"已满足") -> 0 | H18: =COUNTIFS('评估表'!$D$2:$D$241,$A18,'评估表'!$O$2:$O$241,"<="&VALUE(RIGHT($B$10,1)),'评估表'!$K$2:$K$241,"部分满足") -> 0 | I18: =COUNTIFS('评估表'!$D$2:$D$241,$A18,'评估表'!$O$2:$O$241,"<="&VALUE(RIGHT($B$10,1)),'评估表'!$K$2:$K$241,"未满足") -> 0 | J18: =COUNTIFS('评估表'!$D$2:$D$241,$A18,'评估表'!$O$2:$O$241,"<="&VALUE(RIGHT($B$10,1)),'评估表'!$K$2:$K$241,"不适用") -> 0 | K18: =F18-SUM(G18:J18) -> 32 | L18: =IF(F18-J18=0,"—",G18/(F18-J18)) -> 0 | M18: =IF(COUNTIFS('评估表'!$D$2:$D$241,$A18,'评估表'!$O$2:$O$241,"<=1",'评估表'!$K$2:$K$241,"<>已满足",'评估表'!$K$2:$K$241,"<>不适用")>0,"未达 L1",IF(COUNTIFS('评估表'!$D$2:$D$241,$A18,'评估表'!$O$2:$O$241,"<=2",'评估表'!$K$2:$K$241,"<>已满足",'评估表'!$K$2:$K$241,"<>不适用")>0,"L1",IF(COUNTIFS('评估表'!$D$2:$D$241,$A18,'评估表'!$O$2:$O$241,"<=3",'评估表'!$K$2:$K$241,"<>已满足",'评估表'!$K$2:$K$241,"<>不适用")>0,"L2","L3"))) -> 未达 L1
A19: 下游系统 | B19: =COUNTIFS('评估表'!$D$2:$D$241,$A19,'评估表'!$F$2:$F$241,"L1") -> 2 | C19: =COUNTIFS('评估表'!$D$2:$D$241,$A19,'评估表'!$F$2:$F$241,"L2") -> 2 | D19: =COUNTIFS('评估表'!$D$2:$D$241,$A19,'评估表'!$F$2:$F$241,"L3") -> 0 | E19: =SUM(B19:D19) -> 4 | F19: =COUNTIFS('评估表'!$D$2:$D$241,$A19,'评估表'!$O$2:$O$241,"<="&VALUE(RIGHT($B$10,1))) -> 4 | G19: =COUNTIFS('评估表'!$D$2:$D$241,$A19,'评估表'!$O$2:$O$241,"<="&VALUE(RIGHT($B$10,1)),'评估表'!$K$2:$K$241,"已满足") -> 0 | H19: =COUNTIFS('评估表'!$D$2:$D$241,$A19,'评估表'!$O$2:$O$241,"<="&VALUE(RIGHT($B$10,1)),'评估表'!$K$2:$K$241,"部分满足") -> 0 | I19: =COUNTIFS('评估表'!$D$2:$D$241,$A19,'评估表'!$O$2:$O$241,"<="&VALUE(RIGHT($B$10,1)),'评估表'!$K$2:$K$241,"未满足") -> 0 | J19: =COUNTIFS('评估表'!$D$2:$D$241,$A19,'评估表'!$O$2:$O$241,"<="&VALUE(RIGHT($B$10,1)),'评估表'!$K$2:$K$241,"不适用") -> 0 | K19: =F19-SUM(G19:J19) -> 4 | L19: =IF(F19-J19=0,"—",G19/(F19-J19)) -> 0 | M19: =IF(COUNTIFS('评估表'!$D$2:$D$241,$A19,'评估表'!$O$2:$O$241,"<=1",'评估表'!$K$2:$K$241,"<>已满足",'评估表'!$K$2:$K$241,"<>不适用")>0,"未达 L1",IF(COUNTIFS('评估表'!$D$2:$D$241,$A19,'评估表'!$O$2:$O$241,"<=2",'评估表'!$K$2:$K$241,"<>已满足",'评估表'!$K$2:$K$241,"<>不适用")>0,"L1",IF(COUNTIFS('评估表'!$D$2:$D$241,$A19,'评估表'!$O$2:$O$241,"<=3",'评估表'!$K$2:$K$241,"<>已满足",'评估表'!$K$2:$K$241,"<>不适用")>0,"L2","L3"))) -> 未达 L1
A20: 数据层 | B20: =COUNTIFS('评估表'!$D$2:$D$241,$A20,'评估表'!$F$2:$F$241,"L1") -> 3 | C20: =COUNTIFS('评估表'!$D$2:$D$241,$A20,'评估表'!$F$2:$F$241,"L2") -> 11 | D20: =COUNTIFS('评估表'!$D$2:$D$241,$A20,'评估表'!$F$2:$F$241,"L3") -> 0 | E20: =SUM(B20:D20) -> 14 | F20: =COUNTIFS('评估表'!$D$2:$D$241,$A20,'评估表'!$O$2:$O$241,"<="&VALUE(RIGHT($B$10,1))) -> 14 | G20: =COUNTIFS('评估表'!$D$2:$D$241,$A20,'评估表'!$O$2:$O$241,"<="&VALUE(RIGHT($B$10,1)),'评估表'!$K$2:$K$241,"已满足") -> 0 | H20: =COUNTIFS('评估表'!$D$2:$D$241,$A20,'评估表'!$O$2:$O$241,"<="&VALUE(RIGHT($B$10,1)),'评估表'!$K$2:$K$241,"部分满足") -> 0 | I20: =COUNTIFS('评估表'!$D$2:$D$241,$A20,'评估表'!$O$2:$O$241,"<="&VALUE(RIGHT($B$10,1)),'评估表'!$K$2:$K$241,"未满足") -> 0 | J20: =COUNTIFS('评估表'!$D$2:$D$241,$A20,'评估表'!$O$2:$O$241,"<="&VALUE(RIGHT($B$10,1)),'评估表'!$K$2:$K$241,"不适用") -> 0 | K20: =F20-SUM(G20:J20) -> 14 | L20: =IF(F20-J20=0,"—",G20/(F20-J20)) -> 0 | M20: =IF(COUNTIFS('评估表'!$D$2:$D$241,$A20,'评估表'!$O$2:$O$241,"<=1",'评估表'!$K$2:$K$241,"<>已满足",'评估表'!$K$2:$K$241,"<>不适用")>0,"未达 L1",IF(COUNTIFS('评估表'!$D$2:$D$241,$A20,'评估表'!$O$2:$O$241,"<=2",'评估表'!$K$2:$K$241,"<>已满足",'评估表'!$K$2:$K$241,"<>不适用")>0,"L1",IF(COUNTIFS('评估表'!$D$2:$D$241,$A20,'评估表'!$O$2:$O$241,"<=3",'评估表'!$K$2:$K$241,"<>已满足",'评估表'!$K$2:$K$241,"<>不适用")>0,"L2","L3"))) -> 未达 L1
A21: 执行环境 | B21: =COUNTIFS('评估表'!$D$2:$D$241,$A21,'评估表'!$F$2:$F$241,"L1") -> 7 | C21: =COUNTIFS('评估表'!$D$2:$D$241,$A21,'评估表'!$F$2:$F$241,"L2") -> 6 | D21: =COUNTIFS('评估表'!$D$2:$D$241,$A21,'评估表'!$F$2:$F$241,"L3") -> 0 | E21: =SUM(B21:D21) -> 13 | F21: =COUNTIFS('评估表'!$D$2:$D$241,$A21,'评估表'!$O$2:$O$241,"<="&VALUE(RIGHT($B$10,1))) -> 13 | G21: =COUNTIFS('评估表'!$D$2:$D$241,$A21,'评估表'!$O$2:$O$241,"<="&VALUE(RIGHT($B$10,1)),'评估表'!$K$2:$K$241,"已满足") -> 0 | H21: =COUNTIFS('评估表'!$D$2:$D$241,$A21,'评估表'!$O$2:$O$241,"<="&VALUE(RIGHT($B$10,1)),'评估表'!$K$2:$K$241,"部分满足") -> 0 | I21: =COUNTIFS('评估表'!$D$2:$D$241,$A21,'评估表'!$O$2:$O$241,"<="&VALUE(RIGHT($B$10,1)),'评估表'!$K$2:$K$241,"未满足") -> 0 | J21: =COUNTIFS('评估表'!$D$2:$D$241,$A21,'评估表'!$O$2:$O$241,"<="&VALUE(RIGHT($B$10,1)),'评估表'!$K$2:$K$241,"不适用") -> 0 | K21: =F21-SUM(G21:J21) -> 13 | L21: =IF(F21-J21=0,"—",G21/(F21-J21)) -> 0 | M21: =IF(COUNTIFS('评估表'!$D$2:$D$241,$A21,'评估表'!$O$2:$O$241,"<=1",'评估表'!$K$2:$K$241,"<>已满足",'评估表'!$K$2:$K$241,"<>不适用")>0,"未达 L1",IF(COUNTIFS('评估表'!$D$2:$D$241,$A21,'评估表'!$O$2:$O$241,"<=2",'评估表'!$K$2:$K$241,"<>已满足",'评估表'!$K$2:$K$241,"<>不适用")>0,"L1",IF(COUNTIFS('评估表'!$D$2:$D$241,$A21,'评估表'!$O$2:$O$241,"<=3",'评估表'!$K$2:$K$241,"<>已满足",'评估表'!$K$2:$K$241,"<>不适用")>0,"L2","L3"))) -> 未达 L1
A22: 管理面 | B22: =COUNTIFS('评估表'!$D$2:$D$241,$A22,'评估表'!$F$2:$F$241,"L1") -> 13 | C22: =COUNTIFS('评估表'!$D$2:$D$241,$A22,'评估表'!$F$2:$F$241,"L2") -> 26 | D22: =COUNTIFS('评估表'!$D$2:$D$241,$A22,'评估表'!$F$2:$F$241,"L3") -> 1 | E22: =SUM(B22:D22) -> 40 | F22: =COUNTIFS('评估表'!$D$2:$D$241,$A22,'评估表'!$O$2:$O$241,"<="&VALUE(RIGHT($B$10,1))) -> 39 | G22: =COUNTIFS('评估表'!$D$2:$D$241,$A22,'评估表'!$O$2:$O$241,"<="&VALUE(RIGHT($B$10,1)),'评估表'!$K$2:$K$241,"已满足") -> 0 | H22: =COUNTIFS('评估表'!$D$2:$D$241,$A22,'评估表'!$O$2:$O$241,"<="&VALUE(RIGHT($B$10,1)),'评估表'!$K$2:$K$241,"部分满足") -> 0 | I22: =COUNTIFS('评估表'!$D$2:$D$241,$A22,'评估表'!$O$2:$O$241,"<="&VALUE(RIGHT($B$10,1)),'评估表'!$K$2:$K$241,"未满足") -> 0 | J22: =COUNTIFS('评估表'!$D$2:$D$241,$A22,'评估表'!$O$2:$O$241,"<="&VALUE(RIGHT($B$10,1)),'评估表'!$K$2:$K$241,"不适用") -> 0 | K22: =F22-SUM(G22:J22) -> 39 | L22: =IF(F22-J22=0,"—",G22/(F22-J22)) -> 0 | M22: =IF(COUNTIFS('评估表'!$D$2:$D$241,$A22,'评估表'!$O$2:$O$241,"<=1",'评估表'!$K$2:$K$241,"<>已满足",'评估表'!$K$2:$K$241,"<>不适用")>0,"未达 L1",IF(COUNTIFS('评估表'!$D$2:$D$241,$A22,'评估表'!$O$2:$O$241,"<=2",'评估表'!$K$2:$K$241,"<>已满足",'评估表'!$K$2:$K$241,"<>不适用")>0,"L1",IF(COUNTIFS('评估表'!$D$2:$D$241,$A22,'评估表'!$O$2:$O$241,"<=3",'评估表'!$K$2:$K$241,"<>已满足",'评估表'!$K$2:$K$241,"<>不适用")>0,"L2","L3"))) -> 未达 L1
A23: 审计 | B23: =COUNTIFS('评估表'!$D$2:$D$241,$A23,'评估表'!$F$2:$F$241,"L1") -> 4 | C23: =COUNTIFS('评估表'!$D$2:$D$241,$A23,'评估表'!$F$2:$F$241,"L2") -> 14 | D23: =COUNTIFS('评估表'!$D$2:$D$241,$A23,'评估表'!$F$2:$F$241,"L3") -> 2 | E23: =SUM(B23:D23) -> 20 | F23: =COUNTIFS('评估表'!$D$2:$D$241,$A23,'评估表'!$O$2:$O$241,"<="&VALUE(RIGHT($B$10,1))) -> 18 | G23: =COUNTIFS('评估表'!$D$2:$D$241,$A23,'评估表'!$O$2:$O$241,"<="&VALUE(RIGHT($B$10,1)),'评估表'!$K$2:$K$241,"已满足") -> 0 | H23: =COUNTIFS('评估表'!$D$2:$D$241,$A23,'评估表'!$O$2:$O$241,"<="&VALUE(RIGHT($B$10,1)),'评估表'!$K$2:$K$241,"部分满足") -> 0 | I23: =COUNTIFS('评估表'!$D$2:$D$241,$A23,'评估表'!$O$2:$O$241,"<="&VALUE(RIGHT($B$10,1)),'评估表'!$K$2:$K$241,"未满足") -> 0 | J23: =COUNTIFS('评估表'!$D$2:$D$241,$A23,'评估表'!$O$2:$O$241,"<="&VALUE(RIGHT($B$10,1)),'评估表'!$K$2:$K$241,"不适用") -> 0 | K23: =F23-SUM(G23:J23) -> 18 | L23: =IF(F23-J23=0,"—",G23/(F23-J23)) -> 0 | M23: =IF(COUNTIFS('评估表'!$D$2:$D$241,$A23,'评估表'!$O$2:$O$241,"<=1",'评估表'!$K$2:$K$241,"<>已满足",'评估表'!$K$2:$K$241,"<>不适用")>0,"未达 L1",IF(COUNTIFS('评估表'!$D$2:$D$241,$A23,'评估表'!$O$2:$O$241,"<=2",'评估表'!$K$2:$K$241,"<>已满足",'评估表'!$K$2:$K$241,"<>不适用")>0,"L1",IF(COUNTIFS('评估表'!$D$2:$D$241,$A23,'评估表'!$O$2:$O$241,"<=3",'评估表'!$K$2:$K$241,"<>已满足",'评估表'!$K$2:$K$241,"<>不适用")>0,"L2","L3"))) -> 未达 L1
A24: 合计 | B24: =SUM(B14:B23) -> 90 | C24: =SUM(C14:C23) -> 137 | D24: =SUM(D14:D23) -> 13 | E24: =SUM(E14:E23) -> 240 | F24: =SUM(F14:F23) -> 227 | G24: =SUM(G14:G23) -> 0 | H24: =SUM(H14:H23) -> 0 | I24: =SUM(I14:I23) -> 0 | ... K24: =SUM(K14:K23) -> 227 | L24: =IF(F24-J24=0,"—",G24/(F24-J24)) -> 0 | M24: =IF(COUNTIFS('评估表'!$O$2:$O$241,"<=1",'评估表'!$K$2:$K$241,"<>已满足",'评估表'!$K$2:$K$241,"<>不适用")>0,"未达 L1",IF(COUNTIFS('评估表'!$O$2:$O$241,"<=2",'评估表'!$K$2:$K$241,"<>已满足",'评估表'!$K$2:$K$241,"<>不适用")>0,"L1",IF(COUNTIFS('评估表'!$O$2:$O$241,"<=3",'评估表'!$K$2:$K$241,"<>已满足",'评估表'!$K$2:$K$241,"<>不适用")>0,"L2","L3"))) -> 未达 L1
A27: 按章
A28: 章 | B28: L1 | C28: L2 新增 | D28: L3 新增 | E28: 合计 | F28: 目标内条目 | G28: 已满足 | H28: 部分满足 | I28: 未满足 | J28: 不适用 | K28: 未评估 | L28: 满足率 | M28: 达成等级
A29: V1 身份与认证 | B29: =COUNTIFS('评估表'!$B$2:$B$241,$A29,'评估表'!$F$2:$F$241,"L1") -> 11 | C29: =COUNTIFS('评估表'!$B$2:$B$241,$A29,'评估表'!$F$2:$F$241,"L2") -> 11 | D29: =COUNTIFS('评估表'!$B$2:$B$241,$A29,'评估表'!$F$2:$F$241,"L3") -> 1 | E29: =SUM(B29:D29) -> 23 | F29: =COUNTIFS('评估表'!$B$2:$B$241,$A29,'评估表'!$O$2:$O$241,"<="&VALUE(RIGHT($B$10,1))) -> 22 | G29: =COUNTIFS('评估表'!$B$2:$B$241,$A29,'评估表'!$O$2:$O$241,"<="&VALUE(RIGHT($B$10,1)),'评估表'!$K$2:$K$241,"已满足") -> 0 | H29: =COUNTIFS('评估表'!$B$2:$B$241,$A29,'评估表'!$O$2:$O$241,"<="&VALUE(RIGHT($B$10,1)),'评估表'!$K$2:$K$241,"部分满足") -> 0 | I29: =COUNTIFS('评估表'!$B$2:$B$241,$A29,'评估表'!$O$2:$O$241,"<="&VALUE(RIGHT($B$10,1)),'评估表'!$K$2:$K$241,"未满足") -> 0 | J29: =COUNTIFS('评估表'!$B$2:$B$241,$A29,'评估表'!$O$2:$O$241,"<="&VALUE(RIGHT($B$10,1)),'评估表'!$K$2:$K$241,"不适用") -> 0 | K29: =F29-SUM(G29:J29) -> 22 | L29: =IF(F29-J29=0,"—",G29/(F29-J29)) -> 0 | M29: =IF(COUNTIFS('评估表'!$B$2:$B$241,$A29,'评估表'!$O$2:$O$241,"<=1",'评估表'!$K$2:$K$241,"<>已满足",'评估表'!$K$2:$K$241,"<>不适用")>0,"未达 L1",IF(COUNTIFS('评估表'!$B$2:$B$241,$A29,'评估表'!$O$2:$O$241,"<=2",'评估表'!$K$2:$K$241,"<>已满足",'评估表'!$K$2:$K$241,"<>不适用")>0,"L1",IF(COUNTIFS('评估表'!$B$2:$B$241,$A29,'评估表'!$O$2:$O$241,"<=3",'评估表'!$K$2:$K$241,"<>已满足",'评估表'!$K$2:$K$241,"<>不适用")>0,"L2","L3"))) -> 未达 L1
A30: V2 委托与有效权限 | B30: =COUNTIFS('评估表'!$B$2:$B$241,$A30,'评估表'!$F$2:$F$241,"L1") -> 11 | C30: =COUNTIFS('评估表'!$B$2:$B$241,$A30,'评估表'!$F$2:$F$241,"L2") -> 14 | D30: =COUNTIFS('评估表'!$B$2:$B$241,$A30,'评估表'!$F$2:$F$241,"L3") -> 3 | E30: =SUM(B30:D30) -> 28 | F30: =COUNTIFS('评估表'!$B$2:$B$241,$A30,'评估表'!$O$2:$O$241,"<="&VALUE(RIGHT($B$10,1))) -> 25 | G30: =COUNTIFS('评估表'!$B$2:$B$241,$A30,'评估表'!$O$2:$O$241,"<="&VALUE(RIGHT($B$10,1)),'评估表'!$K$2:$K$241,"已满足") -> 0 | H30: =COUNTIFS('评估表'!$B$2:$B$241,$A30,'评估表'!$O$2:$O$241,"<="&VALUE(RIGHT($B$10,1)),'评估表'!$K$2:$K$241,"部分满足") -> 0 | I30: =COUNTIFS('评估表'!$B$2:$B$241,$A30,'评估表'!$O$2:$O$241,"<="&VALUE(RIGHT($B$10,1)),'评估表'!$K$2:$K$241,"未满足") -> 0 | J30: =COUNTIFS('评估表'!$B$2:$B$241,$A30,'评估表'!$O$2:$O$241,"<="&VALUE(RIGHT($B$10,1)),'评估表'!$K$2:$K$241,"不适用") -> 0 | K30: =F30-SUM(G30:J30) -> 25 | L30: =IF(F30-J30=0,"—",G30/(F30-J30)) -> 0 | M30: =IF(COUNTIFS('评估表'!$B$2:$B$241,$A30,'评估表'!$O$2:$O$241,"<=1",'评估表'!$K$2:$K$241,"<>已满足",'评估表'!$K$2:$K$241,"<>不适用")>0,"未达 L1",IF(COUNTIFS('评估表'!$B$2:$B$241,$A30,'评估表'!$O$2:$O$241,"<=2",'评估表'!$K$2:$K$241,"<>已满足",'评估表'!$K$2:$K$241,"<>不适用")>0,"L1",IF(COUNTIFS('评估表'!$B$2:$B$241,$A30,'评估表'!$O$2:$O$241,"<=3",'评估表'!$K$2:$K$241,"<>已满足",'评估表'!$K$2:$K$241,"<>不适用")>0,"L2","L3"))) -> 未达 L1
A31: V3 授权决策 | B31: =COUNTIFS('评估表'!$B$2:$B$241,$A31,'评估表'!$F$2:$F$241,"L1") -> 9 | C31: =COUNTIFS('评估表'!$B$2:$B$241,$A31,'评估表'!$F$2:$F$241,"L2") -> 16 | D31: =COUNTIFS('评估表'!$B$2:$B$241,$A31,'评估表'!$F$2:$F$241,"L3") -> 2 | E31: =SUM(B31:D31) -> 27 | F31: =COUNTIFS('评估表'!$B$2:$B$241,$A31,'评估表'!$O$2:$O$241,"<="&VALUE(RIGHT($B$10,1))) -> 25 | G31: =COUNTIFS('评估表'!$B$2:$B$241,$A31,'评估表'!$O$2:$O$241,"<="&VALUE(RIGHT($B$10,1)),'评估表'!$K$2:$K$241,"已满足") -> 0 | H31: =COUNTIFS('评估表'!$B$2:$B$241,$A31,'评估表'!$O$2:$O$241,"<="&VALUE(RIGHT($B$10,1)),'评估表'!$K$2:$K$241,"部分满足") -> 0 | I31: =COUNTIFS('评估表'!$B$2:$B$241,$A31,'评估表'!$O$2:$O$241,"<="&VALUE(RIGHT($B$10,1)),'评估表'!$K$2:$K$241,"未满足") -> 0 | J31: =COUNTIFS('评估表'!$B$2:$B$241,$A31,'评估表'!$O$2:$O$241,"<="&VALUE(RIGHT($B$10,1)),'评估表'!$K$2:$K$241,"不适用") -> 0 | K31: =F31-SUM(G31:J31) -> 25 | L31: =IF(F31-J31=0,"—",G31/(F31-J31)) -> 0 | M31: =IF(COUNTIFS('评估表'!$B$2:$B$241,$A31,'评估表'!$O$2:$O$241,"<=1",'评估表'!$K$2:$K$241,"<>已满足",'评估表'!$K$2:$K$241,"<>不适用")>0,"未达 L1",IF(COUNTIFS('评估表'!$B$2:$B$241,$A31,'评估表'!$O$2:$O$241,"<=2",'评估表'!$K$2:$K$241,"<>已满足",'评估表'!$K$2:$K$241,"<>不适用")>0,"L1",IF(COUNTIFS('评估表'!$B$2:$B$241,$A31,'评估表'!$O$2:$O$241,"<=3",'评估表'!$K$2:$K$241,"<>已满足",'评估表'!$K$2:$K$241,"<>不适用")>0,"L2","L3"))) -> 未达 L1
A32: V4 凭证与出口执行 | B32: =COUNTIFS('评估表'!$B$2:$B$241,$A32,'评估表'!$F$2:$F$241,"L1") -> 14 | C32: =COUNTIFS('评估表'!$B$2:$B$241,$A32,'评估表'!$F$2:$F$241,"L2") -> 18 | D32: =COUNTIFS('评估表'!$B$2:$B$241,$A32,'评估表'!$F$2:$F$241,"L3") -> 1 | E32: =SUM(B32:D32) -> 33 | F32: =COUNTIFS('评估表'!$B$2:$B$241,$A32,'评估表'!$O$2:$O$241,"<="&VALUE(RIGHT($B$10,1))) -> 32 | G32: =COUNTIFS('评估表'!$B$2:$B$241,$A32,'评估表'!$O$2:$O$241,"<="&VALUE(RIGHT($B$10,1)),'评估表'!$K$2:$K$241,"已满足") -> 0 | H32: =COUNTIFS('评估表'!$B$2:$B$241,$A32,'评估表'!$O$2:$O$241,"<="&VALUE(RIGHT($B$10,1)),'评估表'!$K$2:$K$241,"部分满足") -> 0 | I32: =COUNTIFS('评估表'!$B$2:$B$241,$A32,'评估表'!$O$2:$O$241,"<="&VALUE(RIGHT($B$10,1)),'评估表'!$K$2:$K$241,"未满足") -> 0 | J32: =COUNTIFS('评估表'!$B$2:$B$241,$A32,'评估表'!$O$2:$O$241,"<="&VALUE(RIGHT($B$10,1)),'评估表'!$K$2:$K$241,"不适用") -> 0 | K32: =F32-SUM(G32:J32) -> 32 | L32: =IF(F32-J32=0,"—",G32/(F32-J32)) -> 0 | M32: =IF(COUNTIFS('评估表'!$B$2:$B$241,$A32,'评估表'!$O$2:$O$241,"<=1",'评估表'!$K$2:$K$241,"<>已满足",'评估表'!$K$2:$K$241,"<>不适用")>0,"未达 L1",IF(COUNTIFS('评估表'!$B$2:$B$241,$A32,'评估表'!$O$2:$O$241,"<=2",'评估表'!$K$2:$K$241,"<>已满足",'评估表'!$K$2:$K$241,"<>不适用")>0,"L1",IF(COUNTIFS('评估表'!$B$2:$B$241,$A32,'评估表'!$O$2:$O$241,"<=3",'评估表'!$K$2:$K$241,"<>已满足",'评估表'!$K$2:$K$241,"<>不适用")>0,"L2","L3"))) -> 未达 L1
A33: V5 执行隔离 | B33: =COUNTIFS('评估表'!$B$2:$B$241,$A33,'评估表'!$F$2:$F$241,"L1") -> 16 | C33: =COUNTIFS('评估表'!$B$2:$B$241,$A33,'评估表'!$F$2:$F$241,"L2") -> 11 | D33: =COUNTIFS('评估表'!$B$2:$B$241,$A33,'评估表'!$F$2:$F$241,"L3") -> 0 | E33: =SUM(B33:D33) -> 27 | F33: =COUNTIFS('评估表'!$B$2:$B$241,$A33,'评估表'!$O$2:$O$241,"<="&VALUE(RIGHT($B$10,1))) -> 27 | G33: =COUNTIFS('评估表'!$B$2:$B$241,$A33,'评估表'!$O$2:$O$241,"<="&VALUE(RIGHT($B$10,1)),'评估表'!$K$2:$K$241,"已满足") -> 0 | H33: =COUNTIFS('评估表'!$B$2:$B$241,$A33,'评估表'!$O$2:$O$241,"<="&VALUE(RIGHT($B$10,1)),'评估表'!$K$2:$K$241,"部分满足") -> 0 | I33: =COUNTIFS('评估表'!$B$2:$B$241,$A33,'评估表'!$O$2:$O$241,"<="&VALUE(RIGHT($B$10,1)),'评估表'!$K$2:$K$241,"未满足") -> 0 | J33: =COUNTIFS('评估表'!$B$2:$B$241,$A33,'评估表'!$O$2:$O$241,"<="&VALUE(RIGHT($B$10,1)),'评估表'!$K$2:$K$241,"不适用") -> 0 | K33: =F33-SUM(G33:J33) -> 27 | L33: =IF(F33-J33=0,"—",G33/(F33-J33)) -> 0 | M33: =IF(COUNTIFS('评估表'!$B$2:$B$241,$A33,'评估表'!$O$2:$O$241,"<=1",'评估表'!$K$2:$K$241,"<>已满足",'评估表'!$K$2:$K$241,"<>不适用")>0,"未达 L1",IF(COUNTIFS('评估表'!$B$2:$B$241,$A33,'评估表'!$O$2:$O$241,"<=2",'评估表'!$K$2:$K$241,"<>已满足",'评估表'!$K$2:$K$241,"<>不适用")>0,"L1",IF(COUNTIFS('评估表'!$B$2:$B$241,$A33,'评估表'!$O$2:$O$241,"<=3",'评估表'!$K$2:$K$241,"<>已满足",'评估表'!$K$2:$K$241,"<>不适用")>0,"L2","L3"))) -> 未达 L1
A34: V6 上下文与不可信输入 | B34: =COUNTIFS('评估表'!$B$2:$B$241,$A34,'评估表'!$F$2:$F$241,"L1") -> 4 | C34: =COUNTIFS('评估表'!$B$2:$B$241,$A34,'评估表'!$F$2:$F$241,"L2") -> 8 | D34: =COUNTIFS('评估表'!$B$2:$B$241,$A34,'评估表'!$F$2:$F$241,"L3") -> 1 | E34: =SUM(B34:D34) -> 13 | F34: =COUNTIFS('评估表'!$B$2:$B$241,$A34,'评估表'!$O$2:$O$241,"<="&VALUE(RIGHT($B$10,1))) -> 12 | G34: =COUNTIFS('评估表'!$B$2:$B$241,$A34,'评估表'!$O$2:$O$241,"<="&VALUE(RIGHT($B$10,1)),'评估表'!$K$2:$K$241,"已满足") -> 0 | H34: =COUNTIFS('评估表'!$B$2:$B$241,$A34,'评估表'!$O$2:$O$241,"<="&VALUE(RIGHT($B$10,1)),'评估表'!$K$2:$K$241,"部分满足") -> 0 | I34: =COUNTIFS('评估表'!$B$2:$B$241,$A34,'评估表'!$O$2:$O$241,"<="&VALUE(RIGHT($B$10,1)),'评估表'!$K$2:$K$241,"未满足") -> 0 | J34: =COUNTIFS('评估表'!$B$2:$B$241,$A34,'评估表'!$O$2:$O$241,"<="&VALUE(RIGHT($B$10,1)),'评估表'!$K$2:$K$241,"不适用") -> 0 | K34: =F34-SUM(G34:J34) -> 12 | L34: =IF(F34-J34=0,"—",G34/(F34-J34)) -> 0 | M34: =IF(COUNTIFS('评估表'!$B$2:$B$241,$A34,'评估表'!$O$2:$O$241,"<=1",'评估表'!$K$2:$K$241,"<>已满足",'评估表'!$K$2:$K$241,"<>不适用")>0,"未达 L1",IF(COUNTIFS('评估表'!$B$2:$B$241,$A34,'评估表'!$O$2:$O$241,"<=2",'评估表'!$K$2:$K$241,"<>已满足",'评估表'!$K$2:$K$241,"<>不适用")>0,"L1",IF(COUNTIFS('评估表'!$B$2:$B$241,$A34,'评估表'!$O$2:$O$241,"<=3",'评估表'!$K$2:$K$241,"<>已满足",'评估表'!$K$2:$K$241,"<>不适用")>0,"L2","L3"))) -> 未达 L1
A35: V7 输出与可见性 | B35: =COUNTIFS('评估表'!$B$2:$B$241,$A35,'评估表'!$F$2:$F$241,"L1") -> 6 | C35: =COUNTIFS('评估表'!$B$2:$B$241,$A35,'评估表'!$F$2:$F$241,"L2") -> 12 | D35: =COUNTIFS('评估表'!$B$2:$B$241,$A35,'评估表'!$F$2:$F$241,"L3") -> 0 | E35: =SUM(B35:D35) -> 18 | F35: =COUNTIFS('评估表'!$B$2:$B$241,$A35,'评估表'!$O$2:$O$241,"<="&VALUE(RIGHT($B$10,1))) -> 18 | G35: =COUNTIFS('评估表'!$B$2:$B$241,$A35,'评估表'!$O$2:$O$241,"<="&VALUE(RIGHT($B$10,1)),'评估表'!$K$2:$K$241,"已满足") -> 0 | H35: =COUNTIFS('评估表'!$B$2:$B$241,$A35,'评估表'!$O$2:$O$241,"<="&VALUE(RIGHT($B$10,1)),'评估表'!$K$2:$K$241,"部分满足") -> 0 | I35: =COUNTIFS('评估表'!$B$2:$B$241,$A35,'评估表'!$O$2:$O$241,"<="&VALUE(RIGHT($B$10,1)),'评估表'!$K$2:$K$241,"未满足") -> 0 | J35: =COUNTIFS('评估表'!$B$2:$B$241,$A35,'评估表'!$O$2:$O$241,"<="&VALUE(RIGHT($B$10,1)),'评估表'!$K$2:$K$241,"不适用") -> 0 | K35: =F35-SUM(G35:J35) -> 18 | L35: =IF(F35-J35=0,"—",G35/(F35-J35)) -> 0 | M35: =IF(COUNTIFS('评估表'!$B$2:$B$241,$A35,'评估表'!$O$2:$O$241,"<=1",'评估表'!$K$2:$K$241,"<>已满足",'评估表'!$K$2:$K$241,"<>不适用")>0,"未达 L1",IF(COUNTIFS('评估表'!$B$2:$B$241,$A35,'评估表'!$O$2:$O$241,"<=2",'评估表'!$K$2:$K$241,"<>已满足",'评估表'!$K$2:$K$241,"<>不适用")>0,"L1",IF(COUNTIFS('评估表'!$B$2:$B$241,$A35,'评估表'!$O$2:$O$241,"<=3",'评估表'!$K$2:$K$241,"<>已满足",'评估表'!$K$2:$K$241,"<>不适用")>0,"L2","L3"))) -> 未达 L1
A36: V8 数据、记忆与产出物 | B36: =COUNTIFS('评估表'!$B$2:$B$241,$A36,'评估表'!$F$2:$F$241,"L1") -> 5 | C36: =COUNTIFS('评估表'!$B$2:$B$241,$A36,'评估表'!$F$2:$F$241,"L2") -> 16 | D36: =COUNTIFS('评估表'!$B$2:$B$241,$A36,'评估表'!$F$2:$F$241,"L3") -> 1 | E36: =SUM(B36:D36) -> 22 | F36: =COUNTIFS('评估表'!$B$2:$B$241,$A36,'评估表'!$O$2:$O$241,"<="&VALUE(RIGHT($B$10,1))) -> 21 | G36: =COUNTIFS('评估表'!$B$2:$B$241,$A36,'评估表'!$O$2:$O$241,"<="&VALUE(RIGHT($B$10,1)),'评估表'!$K$2:$K$241,"已满足") -> 0 | H36: =COUNTIFS('评估表'!$B$2:$B$241,$A36,'评估表'!$O$2:$O$241,"<="&VALUE(RIGHT($B$10,1)),'评估表'!$K$2:$K$241,"部分满足") -> 0 | I36: =COUNTIFS('评估表'!$B$2:$B$241,$A36,'评估表'!$O$2:$O$241,"<="&VALUE(RIGHT($B$10,1)),'评估表'!$K$2:$K$241,"未满足") -> 0 | J36: =COUNTIFS('评估表'!$B$2:$B$241,$A36,'评估表'!$O$2:$O$241,"<="&VALUE(RIGHT($B$10,1)),'评估表'!$K$2:$K$241,"不适用") -> 0 | K36: =F36-SUM(G36:J36) -> 21 | L36: =IF(F36-J36=0,"—",G36/(F36-J36)) -> 0 | M36: =IF(COUNTIFS('评估表'!$B$2:$B$241,$A36,'评估表'!$O$2:$O$241,"<=1",'评估表'!$K$2:$K$241,"<>已满足",'评估表'!$K$2:$K$241,"<>不适用")>0,"未达 L1",IF(COUNTIFS('评估表'!$B$2:$B$241,$A36,'评估表'!$O$2:$O$241,"<=2",'评估表'!$K$2:$K$241,"<>已满足",'评估表'!$K$2:$K$241,"<>不适用")>0,"L1",IF(COUNTIFS('评估表'!$B$2:$B$241,$A36,'评估表'!$O$2:$O$241,"<=3",'评估表'!$K$2:$K$241,"<>已满足",'评估表'!$K$2:$K$241,"<>不适用")>0,"L2","L3"))) -> 未达 L1
A37: V9 生命周期与治理 | B37: =COUNTIFS('评估表'!$B$2:$B$241,$A37,'评估表'!$F$2:$F$241,"L1") -> 9 | C37: =COUNTIFS('评估表'!$B$2:$B$241,$A37,'评估表'!$F$2:$F$241,"L2") -> 16 | D37: =COUNTIFS('评估表'!$B$2:$B$241,$A37,'评估表'!$F$2:$F$241,"L3") -> 1 | E37: =SUM(B37:D37) -> 26 | F37: =COUNTIFS('评估表'!$B$2:$B$241,$A37,'评估表'!$O$2:$O$241,"<="&VALUE(RIGHT($B$10,1))) -> 25 | G37: =COUNTIFS('评估表'!$B$2:$B$241,$A37,'评估表'!$O$2:$O$241,"<="&VALUE(RIGHT($B$10,1)),'评估表'!$K$2:$K$241,"已满足") -> 0 | H37: =COUNTIFS('评估表'!$B$2:$B$241,$A37,'评估表'!$O$2:$O$241,"<="&VALUE(RIGHT($B$10,1)),'评估表'!$K$2:$K$241,"部分满足") -> 0 | I37: =COUNTIFS('评估表'!$B$2:$B$241,$A37,'评估表'!$O$2:$O$241,"<="&VALUE(RIGHT($B$10,1)),'评估表'!$K$2:$K$241,"未满足") -> 0 | J37: =COUNTIFS('评估表'!$B$2:$B$241,$A37,'评估表'!$O$2:$O$241,"<="&VALUE(RIGHT($B$10,1)),'评估表'!$K$2:$K$241,"不适用") -> 0 | K37: =F37-SUM(G37:J37) -> 25 | L37: =IF(F37-J37=0,"—",G37/(F37-J37)) -> 0 | M37: =IF(COUNTIFS('评估表'!$B$2:$B$241,$A37,'评估表'!$O$2:$O$241,"<=1",'评估表'!$K$2:$K$241,"<>已满足",'评估表'!$K$2:$K$241,"<>不适用")>0,"未达 L1",IF(COUNTIFS('评估表'!$B$2:$B$241,$A37,'评估表'!$O$2:$O$241,"<=2",'评估表'!$K$2:$K$241,"<>已满足",'评估表'!$K$2:$K$241,"<>不适用")>0,"L1",IF(COUNTIFS('评估表'!$B$2:$B$241,$A37,'评估表'!$O$2:$O$241,"<=3",'评估表'!$K$2:$K$241,"<>已满足",'评估表'!$K$2:$K$241,"<>不适用")>0,"L2","L3"))) -> 未达 L1
A38: V10 审计、检测与响应 | B38: =COUNTIFS('评估表'!$B$2:$B$241,$A38,'评估表'!$F$2:$F$241,"L1") -> 5 | C38: =COUNTIFS('评估表'!$B$2:$B$241,$A38,'评估表'!$F$2:$F$241,"L2") -> 15 | D38: =COUNTIFS('评估表'!$B$2:$B$241,$A38,'评估表'!$F$2:$F$241,"L3") -> 3 | E38: =SUM(B38:D38) -> 23 | F38: =COUNTIFS('评估表'!$B$2:$B$241,$A38,'评估表'!$O$2:$O$241,"<="&VALUE(RIGHT($B$10,1))) -> 20 | G38: =COUNTIFS('评估表'!$B$2:$B$241,$A38,'评估表'!$O$2:$O$241,"<="&VALUE(RIGHT($B$10,1)),'评估表'!$K$2:$K$241,"已满足") -> 0 | H38: =COUNTIFS('评估表'!$B$2:$B$241,$A38,'评估表'!$O$2:$O$241,"<="&VALUE(RIGHT($B$10,1)),'评估表'!$K$2:$K$241,"部分满足") -> 0 | I38: =COUNTIFS('评估表'!$B$2:$B$241,$A38,'评估表'!$O$2:$O$241,"<="&VALUE(RIGHT($B$10,1)),'评估表'!$K$2:$K$241,"未满足") -> 0 | J38: =COUNTIFS('评估表'!$B$2:$B$241,$A38,'评估表'!$O$2:$O$241,"<="&VALUE(RIGHT($B$10,1)),'评估表'!$K$2:$K$241,"不适用") -> 0 | K38: =F38-SUM(G38:J38) -> 20 | L38: =IF(F38-J38=0,"—",G38/(F38-J38)) -> 0 | M38: =IF(COUNTIFS('评估表'!$B$2:$B$241,$A38,'评估表'!$O$2:$O$241,"<=1",'评估表'!$K$2:$K$241,"<>已满足",'评估表'!$K$2:$K$241,"<>不适用")>0,"未达 L1",IF(COUNTIFS('评估表'!$B$2:$B$241,$A38,'评估表'!$O$2:$O$241,"<=2",'评估表'!$K$2:$K$241,"<>已满足",'评估表'!$K$2:$K$241,"<>不适用")>0,"L1",IF(COUNTIFS('评估表'!$B$2:$B$241,$A38,'评估表'!$O$2:$O$241,"<=3",'评估表'!$K$2:$K$241,"<>已满足",'评估表'!$K$2:$K$241,"<>不适用")>0,"L2","L3"))) -> 未达 L1
A39: 合计 | B39: =SUM(B29:B38) -> 90 | C39: =SUM(C29:C38) -> 137 | D39: =SUM(D29:D38) -> 13 | E39: =SUM(E29:E38) -> 240 | F39: =SUM(F29:F38) -> 227 | G39: =SUM(G29:G38) -> 0 | H39: =SUM(H29:H38) -> 0 | I39: =SUM(I29:I38) -> 0 | ... K39: =SUM(K29:K38) -> 227 | L39: =IF(F39-J39=0,"—",G39/(F39-J39)) -> 0 | M39: =IF(COUNTIFS('评估表'!$O$2:$O$241,"<=1",'评估表'!$K$2:$K$241,"<>已满足",'评估表'!$K$2:$K$241,"<>不适用")>0,"未达 L1",IF(COUNTIFS('评估表'!$O$2:$O$241,"<=2",'评估表'!$K$2:$K$241,"<>已满足",'评估表'!$K$2:$K$241,"<>不适用")>0,"L1",IF(COUNTIFS('评估表'!$O$2:$O$241,"<=3",'评估表'!$K$2:$K$241,"<>已满足",'评估表'!$K$2:$K$241,"<>不适用")>0,"L2","L3"))) -> 未达 L1
A42: 组件 × 章（全部等级的条目数）
A43: 组件 | B43: V1 | C43: V2 | D43: V3 | E43: V4 | F43: V5 | G43: V6 | H43: V7 | I43: V8 | J43: V9 | K43: V10 | L43: 合计
A44: 身份层 | B44: =COUNTIFS('评估表'!$D$2:$D$241,$A44,'评估表'!$B$2:$B$241,"V1 身份与认证") -> 12 | C44: =COUNTIFS('评估表'!$D$2:$D$241,$A44,'评估表'!$B$2:$B$241,"V2 委托与有效权限") -> 3 | D44: =COUNTIFS('评估表'!$D$2:$D$241,$A44,'评估表'!$B$2:$B$241,"V3 授权决策") -> 1 | E44: =COUNTIFS('评估表'!$D$2:$D$241,$A44,'评估表'!$B$2:$B$241,"V4 凭证与出口执行") -> 4 | F44: =COUNTIFS('评估表'!$D$2:$D$241,$A44,'评估表'!$B$2:$B$241,"V5 执行隔离") -> 1 | G44: =COUNTIFS('评估表'!$D$2:$D$241,$A44,'评估表'!$B$2:$B$241,"V6 上下文与不可信输入") -> 0 | H44: =COUNTIFS('评估表'!$D$2:$D$241,$A44,'评估表'!$B$2:$B$241,"V7 输出与可见性") -> 0 | I44: =COUNTIFS('评估表'!$D$2:$D$241,$A44,'评估表'!$B$2:$B$241,"V8 数据、记忆与产出物") -> 0 | J44: =COUNTIFS('评估表'!$D$2:$D$241,$A44,'评估表'!$B$2:$B$241,"V9 生命周期与治理") -> 1 | K44: =COUNTIFS('评估表'!$D$2:$D$241,$A44,'评估表'!$B$2:$B$241,"V10 审计、检测与响应") -> 0 | L44: =SUM(B44:K44) -> 22
A45: 交互渠道 | B45: =COUNTIFS('评估表'!$D$2:$D$241,$A45,'评估表'!$B$2:$B$241,"V1 身份与认证") -> 6 | C45: =COUNTIFS('评估表'!$D$2:$D$241,$A45,'评估表'!$B$2:$B$241,"V2 委托与有效权限") -> 1 | D45: =COUNTIFS('评估表'!$D$2:$D$241,$A45,'评估表'!$B$2:$B$241,"V3 授权决策") -> 0 | E45: =COUNTIFS('评估表'!$D$2:$D$241,$A45,'评估表'!$B$2:$B$241,"V4 凭证与出口执行") -> 0 | F45: =COUNTIFS('评估表'!$D$2:$D$241,$A45,'评估表'!$B$2:$B$241,"V5 执行隔离") -> 0 | G45: =COUNTIFS('评估表'!$D$2:$D$241,$A45,'评估表'!$B$2:$B$241,"V6 上下文与不可信输入") -> 0 | H45: =COUNTIFS('评估表'!$D$2:$D$241,$A45,'评估表'!$B$2:$B$241,"V7 输出与可见性") -> 10 | I45: =COUNTIFS('评估表'!$D$2:$D$241,$A45,'评估表'!$B$2:$B$241,"V8 数据、记忆与产出物") -> 1 | J45: =COUNTIFS('评估表'!$D$2:$D$241,$A45,'评估表'!$B$2:$B$241,"V9 生命周期与治理") -> 0 | K45: =COUNTIFS('评估表'!$D$2:$D$241,$A45,'评估表'!$B$2:$B$241,"V10 审计、检测与响应") -> 0 | L45: =SUM(B45:K45) -> 18
A46: Harness | B46: =COUNTIFS('评估表'!$D$2:$D$241,$A46,'评估表'!$B$2:$B$241,"V1 身份与认证") -> 1 | C46: =COUNTIFS('评估表'!$D$2:$D$241,$A46,'评估表'!$B$2:$B$241,"V2 委托与有效权限") -> 2 | D46: =COUNTIFS('评估表'!$D$2:$D$241,$A46,'评估表'!$B$2:$B$241,"V3 授权决策") -> 14 | E46: =COUNTIFS('评估表'!$D$2:$D$241,$A46,'评估表'!$B$2:$B$241,"V4 凭证与出口执行") -> 2 | F46: =COUNTIFS('评估表'!$D$2:$D$241,$A46,'评估表'!$B$2:$B$241,"V5 执行隔离") -> 11 | G46: =COUNTIFS('评估表'!$D$2:$D$241,$A46,'评估表'!$B$2:$B$241,"V6 上下文与不可信输入") -> 10 | H46: =COUNTIFS('评估表'!$D$2:$D$241,$A46,'评估表'!$B$2:$B$241,"V7 输出与可见性") -> 4 | I46: =COUNTIFS('评估表'!$D$2:$D$241,$A46,'评估表'!$B$2:$B$241,"V8 数据、记忆与产出物") -> 3 | J46: =COUNTIFS('评估表'!$D$2:$D$241,$A46,'评估表'!$B$2:$B$241,"V9 生命周期与治理") -> 0 | K46: =COUNTIFS('评估表'!$D$2:$D$241,$A46,'评估表'!$B$2:$B$241,"V10 审计、检测与响应") -> 1 | L46: =SUM(B46:K46) -> 48
A47: 策略决策点 | B47: =COUNTIFS('评估表'!$D$2:$D$241,$A47,'评估表'!$B$2:$B$241,"V1 身份与认证") -> 1 | C47: =COUNTIFS('评估表'!$D$2:$D$241,$A47,'评估表'!$B$2:$B$241,"V2 委托与有效权限") -> 15 | D47: =COUNTIFS('评估表'!$D$2:$D$241,$A47,'评估表'!$B$2:$B$241,"V3 授权决策") -> 8 | E47: =COUNTIFS('评估表'!$D$2:$D$241,$A47,'评估表'!$B$2:$B$241,"V4 凭证与出口执行") -> 0 | F47: =COUNTIFS('评估表'!$D$2:$D$241,$A47,'评估表'!$B$2:$B$241,"V5 执行隔离") -> 0 | G47: =COUNTIFS('评估表'!$D$2:$D$241,$A47,'评估表'!$B$2:$B$241,"V6 上下文与不可信输入") -> 0 | H47: =COUNTIFS('评估表'!$D$2:$D$241,$A47,'评估表'!$B$2:$B$241,"V7 输出与可见性") -> 0 | I47: =COUNTIFS('评估表'!$D$2:$D$241,$A47,'评估表'!$B$2:$B$241,"V8 数据、记忆与产出物") -> 1 | J47: =COUNTIFS('评估表'!$D$2:$D$241,$A47,'评估表'!$B$2:$B$241,"V9 生命周期与治理") -> 1 | K47: =COUNTIFS('评估表'!$D$2:$D$241,$A47,'评估表'!$B$2:$B$241,"V10 审计、检测与响应") -> 3 | L47: =SUM(B47:K47) -> 29
A48: 出口网关 | B48: =COUNTIFS('评估表'!$D$2:$D$241,$A48,'评估表'!$B$2:$B$241,"V1 身份与认证") -> 1 | C48: =COUNTIFS('评估表'!$D$2:$D$241,$A48,'评估表'!$B$2:$B$241,"V2 委托与有效权限") -> 2 | D48: =COUNTIFS('评估表'!$D$2:$D$241,$A48,'评估表'!$B$2:$B$241,"V3 授权决策") -> 2 | E48: =COUNTIFS('评估表'!$D$2:$D$241,$A48,'评估表'!$B$2:$B$241,"V4 凭证与出口执行") -> 19 | F48: =COUNTIFS('评估表'!$D$2:$D$241,$A48,'评估表'!$B$2:$B$241,"V5 执行隔离") -> 2 | G48: =COUNTIFS('评估表'!$D$2:$D$241,$A48,'评估表'!$B$2:$B$241,"V6 上下文与不可信输入") -> 0 | H48: =COUNTIFS('评估表'!$D$2:$D$241,$A48,'评估表'!$B$2:$B$241,"V7 输出与可见性") -> 3 | I48: =COUNTIFS('评估表'!$D$2:$D$241,$A48,'评估表'!$B$2:$B$241,"V8 数据、记忆与产出物") -> 3 | J48: =COUNTIFS('评估表'!$D$2:$D$241,$A48,'评估表'!$B$2:$B$241,"V9 生命周期与治理") -> 0 | K48: =COUNTIFS('评估表'!$D$2:$D$241,$A48,'评估表'!$B$2:$B$241,"V10 审计、检测与响应") -> 0 | L48: =SUM(B48:K48) -> 32
...

Sheet 差距清单
A1: 差距清单（目标等级 L2）
A2: 导出时按目标等级内、状态不是「已满足」或「不适用」的要求生成，按等级和编号排序。在评估表里改状态后，这一页不会自动更新，请重新导出。
A3: 编号 | B3: 章 | C3: 落点组件 | D3: 要求 | E3: 最低等级 | F3: 状态 | G3: 负责人 | H3: 计划完成 | I3: 证据与说明
A4: V1.1.1 | B4: V1 身份与认证 | C4: 身份层 | D4: 平台及其全部渠道应只允许通过企业 IdP（OIDC 或 SAML）登录，不提供独立的本地账号，V10.5 规定的紧急访问账号除外 | E4: L1 | F4: 未评估
A5: V1.1.4 | B5: V1 身份与认证 | C5: 身份层 | D5: 通过 API 调用 Agent 的凭证（如 API Key、个人访问令牌）应绑定到企业 IdP 中的具体用户或非人类身份，设置到期时间和权限范围，身份禁用时同步失效 | E5: L1 | F5: 未评估
A6: V1.2.1 | B6: V1 身份与认证 | C6: 交互渠道 | D6: 渠道账号应先通过一次 SSO 登录与企业身份绑定，才能调用 Agent | E6: L1 | F6: 未评估
A7: V1.2.2 | B7: V1 身份与认证 | C7: 交互渠道 | D7: 应以 SSO 绑定结果作为渠道账号的唯一身份依据，不按昵称、显示名或邮箱字符串匹配；邮件渠道按 V1.2.6 执行 | E7: L1 | F7: 未评估
A8: V1.2.6 | B8: V1 身份与认证 | C8: 交互渠道 | D8: 邮件渠道应只受理通过 DMARC 校验的邮件（SPF 或 DKIM 通过且与发件域对齐），外部域的发件人不能触发代表用户的操作 | E8: L1 | F8: 未评估
A9: V1.3.1 | B9: V1 身份与认证 | C9: 身份层 | D9: 每个 Agent 应有平台签发的唯一身份标识，不采信 Agent 自报的身份 | E9: L1 | F9: 未评估
A10: V1.3.2 | B10: V1 身份与认证 | C10: 身份层 | D10: 应为自主 Agent 在企业目录中建立独立的非人类身份，不使用任何员工的个人账号 | E10: L1 | F10: 未评估
A11: V1.4.1 | B11: V1 身份与认证 | C11: 身份层 | D11: 平台应为每个会话的执行实例签发短期工作负载身份，并与该实例绑定 | E11: L1 | F11: 未评估
A12: V1.4.2 | B12: V1 身份与认证 | C12: Harness | D12: 工作负载身份的凭证应对模型不可见，不进入上下文和工具返回 | E12: L1 | F12: 未评估
A13: V1.4.3 | B13: V1 身份与认证 | C13: 出口网关 | D13: 出口网关应只依据工作负载身份确定用户和 Agent，忽略请求中自报的用户或 Agent 标识 | E13: L1 | F13: 未评估
A14: V1.5.2 | B14: V1 身份与认证 | C14: 策略决策点 | D14: 外部主体应只能访问为其开放的工作空间和接口 | E14: L1 | F14: 未评估
A15: V2.1.1 | B15: V2 委托与有效权限 | C15: 出口网关 | D15: 用户在场时，Agent 访问下游应携带发起用户的身份，由下游按该用户作出授权判定；下游不支持用户级授权判定的按 V4.4 执行 | E15: L1 | F15: 未评估
... A230: V10.6.2 | B230: V10 审计、检测与响应 | C230: 审计 | D230: 应能按会话或委托链还原 Agent 在指定时段内的全部操作，用于确定影响范围 | E230: L2 | F230: 未评估

Sheet 架构视角
A1: 架构视角
A2: 对应基线第 4 章。落点组件指主要负责实现或强制执行该要求的组件，多个组件配合时取最主要的一个。
A4: 组件
A5: 组件 | C5: 职责 | D5: 信任假设 | E5: L1 | F5: L2 新增 | G5: L3 新增
A6: 身份层 | C6: 企业 IdP、目录、SCIM，签发用户、Agent 和工作负载身份 | D6: 可信 | E6: =COUNTIFS('评估表'!$D$2:$D$241,$A6,'评估表'!$F$2:$F$241,"L1") -> 7 | F6: =COUNTIFS('评估表'!$D$2:$D$241,$A6,'评估表'!$F$2:$F$241,"L2") -> 12 | G6: =COUNTIFS('评估表'!$D$2:$D$241,$A6,'评估表'!$F$2:$F$241,"L3") -> 3
A7: 交互渠道 | C7: Web、IM、邮件、IDE、API 等入口，负责身份映射和输出的可见范围 | D7: 可信；经渠道进入的内容不可信 | E7: =COUNTIFS('评估表'!$D$2:$D$241,$A7,'评估表'!$F$2:$F$241,"L1") -> 8 | F7: =COUNTIFS('评估表'!$D$2:$D$241,$A7,'评估表'!$F$2:$F$241,"L2") -> 10 | G7: =COUNTIFS('评估表'!$D$2:$D$241,$A7,'评估表'!$F$2:$F$241,"L3") -> 0
A8: Harness | C8: Agent 循环、上下文管理、工具层、安全控制、编排、扩展接口 | D8: 平台托管时可信；在员工终端运行时不可信，按 V5.4 | E8: =COUNTIFS('评估表'!$D$2:$D$241,$A8,'评估表'!$F$2:$F$241,"L1") -> 18 | F8: =COUNTIFS('评估表'!$D$2:$D$241,$A8,'评估表'!$F$2:$F$241,"L2") -> 28 | G8: =COUNTIFS('评估表'!$D$2:$D$241,$A8,'评估表'!$F$2:$F$241,"L3") -> 2
A9: 策略决策点 | C9: 计算有效权限、判定风险等级、决定是否审批 | D9: 可信 | E9: =COUNTIFS('评估表'!$D$2:$D$241,$A9,'评估表'!$F$2:$F$241,"L1") -> 12 | F9: =COUNTIFS('评估表'!$D$2:$D$241,$A9,'评估表'!$F$2:$F$241,"L2") -> 12 | G9: =COUNTIFS('评估表'!$D$2:$D$241,$A9,'评估表'!$F$2:$F$241,"L3") -> 5
A10: 出口网关 | C10: 统一出口，注入凭证、校验目标、限流、吊销；凭证库归属于此 | D10: 可信 | E10: =COUNTIFS('评估表'!$D$2:$D$241,$A10,'评估表'!$F$2:$F$241,"L1") -> 16 | F10: =COUNTIFS('评估表'!$D$2:$D$241,$A10,'评估表'!$F$2:$F$241,"L2") -> 16 | G10: =COUNTIFS('评估表'!$D$2:$D$241,$A10,'评估表'!$F$2:$F$241,"L3") -> 0
A11: 下游系统 | C11: 被访问的 SaaS、内部 API、MCP Server、数据库 | D11: 自行作出授权判定；返回内容不可信 | E11: =COUNTIFS('评估表'!$D$2:$D$241,$A11,'评估表'!$F$2:$F$241,"L1") -> 2 | F11: =COUNTIFS('评估表'!$D$2:$D$241,$A11,'评估表'!$F$2:$F$241,"L2") -> 2 | G11: =COUNTIFS('评估表'!$D$2:$D$241,$A11,'评估表'!$F$2:$F$241,"L3") -> 0
A12: 数据层 | C12: 知识库、RAG、记忆、产出物 | D12: 可信；存储的内容可能被污染，按不可信内容处理 | E12: =COUNTIFS('评估表'!$D$2:$D$241,$A12,'评估表'!$F$2:$F$241,"L1") -> 3 | F12: =COUNTIFS('评估表'!$D$2:$D$241,$A12,'评估表'!$F$2:$F$241,"L2") -> 11 | G12: =COUNTIFS('评估表'!$D$2:$D$241,$A12,'评估表'!$F$2:$F$241,"L3") -> 0
A13: 执行环境 | C13: 执行代码、命令、文件和浏览器操作 | D13: 不可信，可能被攻陷 | E13: =COUNTIFS('评估表'!$D$2:$D$241,$A13,'评估表'!$F$2:$F$241,"L1") -> 7 | F13: =COUNTIFS('评估表'!$D$2:$D$241,$A13,'评估表'!$F$2:$F$241,"L2") -> 6 | G13: =COUNTIFS('评估表'!$D$2:$D$241,$A13,'评估表'!$F$2:$F$241,"L3") -> 0
A14: 管理面 | C14: Agent 登记、连接器、托管策略、生命周期 | D14: 可信 | E14: =COUNTIFS('评估表'!$D$2:$D$241,$A14,'评估表'!$F$2:$F$241,"L1") -> 13 | F14: =COUNTIFS('评估表'!$D$2:$D$241,$A14,'评估表'!$F$2:$F$241,"L2") -> 26 | G14: =COUNTIFS('评估表'!$D$2:$D$241,$A14,'评估表'!$F$2:$F$241,"L3") -> 1
A15: 审计 | C15: 记录、调阅、导出与留存，以及检测与响应 | D15: 可信 | E15: =COUNTIFS('评估表'!$D$2:$D$241,$A15,'评估表'!$F$2:$F$241,"L1") -> 4 | F15: =COUNTIFS('评估表'!$D$2:$D$241,$A15,'评估表'!$F$2:$F$241,"L2") -> 14 | G15: =COUNTIFS('评估表'!$D$2:$D$241,$A15,'评估表'!$F$2:$F$241,"L3") -> 2
A17: 模型不承担任何控制：它的输出只是请求，相关要求落在 Harness 上。
A19: 一次工具调用的检查点
A20: 步骤 | B20: 检查点 | C20: 发生了什么 | D20: 负责组件 | E20: 相关要求
A21: 1 | B21: 入口认证 | C21: 渠道账号映射到企业身份 | D21: 交互渠道、身份层 | E21: V1.1、V1.2
A22: 2 | B22: 建立会话 | C22: 签发工作负载身份，确定用户和 Agent | D22: Harness、身份层 | E22: V1.4
A23: 3 | B23: 组装上下文 | C23: 按有效权限过滤工具清单、记忆和检索结果 | D23: Harness、数据层 | E23: V3.3、V8.1、V8.3
A24: 4 | B24: 前置校验 | C24: 执行前做策略检查和风险分级 | D24: Harness、策略决策点 | E24: V2.2、V3.1、V3.2
A25: 5 | B25: 人工确认 | C25: 按真实参数生成审批，必要时二次认证 | D25: Harness、身份层 | E25: V3.4、V3.5
A26: 6 | B26: 出口执行 | C26: 经网关注入凭证、校验目标、限流 | D26: 出口网关 | E26: V4.1、V4.2、V3.8
A27: 7 | B27: 下游授权判定 | C27: 下游按代表用户访问时传递的用户身份作出授权判定 | D27: 下游系统 | E27: V2.1、V4.3、V4.4
A28: 8 | B28: 处理返回 | C28: 返回内容按不可信处理并标记来源 | D28: Harness | E28: V6.1、V6.2
A29: 9 | B29: 输出检查 | C29: 检查接收方、敏感数据和渲染风险 | D29: 交互渠道、出口网关 | E29: V7.1、V7.4、V7.5
A30: 10 | B30: 全程记录 | C30: 每一步写入审计，可追溯到人、Agent 和输入来源 | D30: 审计 | E30: V10.1

Sheet 说明
A1: 企业智能体身份与授权安全基线 评估表
A2: 对应文档 | B2: 企业智能体身份与授权安全基线 v1.0（2026-10-07）。要求的完整上下文、术语、架构图、威胁模型和映射附录都在文档中。
A3: 文档链接 | B3: https://github.com/teloa-ai/agent-baseline-assessor/blob/main/01-standard/zh-CN/baseline-v1.0.md
A4: 内容 | B4: 共 240 条要求，分布在 62 个小节：L1 90 条，L2 在此基础上增加 137 条，L3 再增加 13 条。
A6: 评估信息
A7: 评估对象
A8: 评估范围
A9: 评估人
A10: 评估日期
A11: 目标等级 | B11: L2
A13: 怎么填
A14: 只填黄色列 | B14: 状态、证据与说明、负责人、计划完成四列由评估者填写，其余列与基线保持一致，不在这里改。
A15: 状态 | B15: 下拉选择：未评估、已满足、部分满足、未满足、不适用。整节因适用条件不成立而不适用时，该节每条都选「不适用」。
A16: 等级 | B16: L1 底线，L2 标准，L3 增强；高等级包含低等级的全部要求。达到某级 = 该级及以下的适用要求全部满足。
A17: 回到网页 | B17: 这份表可以在自评网页的「数据」页导入，状态、证据、负责人和计划完成会按编号回填。
A19: 两个视角
A20: 章 | B20: 回答「要求什么」。V1 至 V7 沿一次 Agent 行为的发生顺序排列，V8 至 V10 按跨会话持续存在的数据、Agent 和审计组织。
A21: 落点组件 | B21: 回答「在哪里实现」，顺序同基线 4.2 组件表。可按组件筛选后分派给对应团队。组件定义和检查点见「架构视角」页。
